[INFO] - [2023-07-01 13:18:57,066] - [file autoreload.py] - [module autoreload] - [func run_with_reloader] - [line_num 668] - Watching for file changes with StatReloader
[INFO] - [2023-07-01 13:19:20,980] - [file autoreload.py] - [module autoreload] - [func trigger_reload] - [line_num 266] - C:\Users\é\Desktop\Python_django_diploma_dpo\backend\api\views\ProfileAPIView.py changed, reloading.
[INFO] - [2023-07-01 13:19:21,919] - [file autoreload.py] - [module autoreload] - [func run_with_reloader] - [line_num 668] - Watching for file changes with StatReloader
[INFO] - [2023-07-01 13:19:35,755] - [file autoreload.py] - [module autoreload] - [func run_with_reloader] - [line_num 668] - Watching for file changes with StatReloader
[INFO] - [2023-07-01 13:25:34,554] - [file autoreload.py] - [module autoreload] - [func trigger_reload] - [line_num 266] - C:\Users\é\Desktop\Python_django_diploma_dpo\backend\backend\settings.py changed, reloading.
[INFO] - [2023-07-01 13:25:35,139] - [file autoreload.py] - [module autoreload] - [func run_with_reloader] - [line_num 668] - Watching for file changes with StatReloader
[INFO] - [2023-07-01 13:25:41,793] - [file autoreload.py] - [module autoreload] - [func run_with_reloader] - [line_num 668] - Watching for file changes with StatReloader
[INFO] - [2023-07-01 13:26:35,610] - [file autoreload.py] - [module autoreload] - [func run_with_reloader] - [line_num 668] - Watching for file changes with StatReloader
[INFO] - [2023-07-01 13:29:01,978] - [file autoreload.py] - [module autoreload] - [func trigger_reload] - [line_num 266] - C:\Users\é\Desktop\Python_django_diploma_dpo\backend\backend\settings.py changed, reloading.
[INFO] - [2023-07-01 13:29:02,584] - [file autoreload.py] - [module autoreload] - [func run_with_reloader] - [line_num 668] - Watching for file changes with StatReloader
[INFO] - [2023-07-01 13:29:21,142] - [file autoreload.py] - [module autoreload] - [func run_with_reloader] - [line_num 668] - Watching for file changes with StatReloader
[INFO] - [2023-07-01 13:32:21,913] - [file autoreload.py] - [module autoreload] - [func run_with_reloader] - [line_num 668] - Watching for file changes with StatReloader
[INFO] - [2023-07-01 13:32:44,486] - [file autoreload.py] - [module autoreload] - [func trigger_reload] - [line_num 266] - C:\Users\é\Desktop\Python_django_diploma_dpo\backend\backend\settings.py changed, reloading.
[INFO] - [2023-07-01 13:32:44,978] - [file autoreload.py] - [module autoreload] - [func run_with_reloader] - [line_num 668] - Watching for file changes with StatReloader
[INFO] - [2023-07-01 13:33:35,784] - [file autoreload.py] - [module autoreload] - [func run_with_reloader] - [line_num 668] - Watching for file changes with StatReloader
[INFO] - [2023-07-01 13:34:04,150] - [file autoreload.py] - [module autoreload] - [func run_with_reloader] - [line_num 668] - Watching for file changes with StatReloader
[INFO] - [2023-07-01 13:34:21,915] - [file autoreload.py] - [module autoreload] - [func trigger_reload] - [line_num 266] - C:\Users\é\Desktop\Python_django_diploma_dpo\backend\api\views\ProfileAPIView.py changed, reloading.
[INFO] - [2023-07-01 13:34:22,566] - [file autoreload.py] - [module autoreload] - [func run_with_reloader] - [line_num 668] - Watching for file changes with StatReloader
[INFO] - [2023-07-01 13:35:27,708] - [file autoreload.py] - [module autoreload] - [func trigger_reload] - [line_num 266] - C:\Users\é\Desktop\Python_django_diploma_dpo\backend\backend\urls.py changed, reloading.
[INFO] - [2023-07-01 13:35:28,444] - [file autoreload.py] - [module autoreload] - [func run_with_reloader] - [line_num 668] - Watching for file changes with StatReloader
[WARNING] - [2023-07-01 13:35:41,315] - [file log.py] - [module log] - [func log_response] - [line_num 241] - Not Found: /sign-in/
[WARNING] - [2023-07-01 13:35:50,025] - [file log.py] - [module log] - [func log_response] - [line_num 241] - Not Found: /
[INFO] - [2023-07-01 13:36:15,923] - [file autoreload.py] - [module autoreload] - [func trigger_reload] - [line_num 266] - C:\Users\é\Desktop\Python_django_diploma_dpo\backend\backend\urls.py changed, reloading.
[INFO] - [2023-07-01 13:36:16,553] - [file autoreload.py] - [module autoreload] - [func run_with_reloader] - [line_num 668] - Watching for file changes with StatReloader
[INFO] - [2023-07-01 13:36:32,358] - [file autoreload.py] - [module autoreload] - [func run_with_reloader] - [line_num 668] - Watching for file changes with StatReloader
[INFO] - [2023-07-01 13:36:41,000] - [file autoreload.py] - [module autoreload] - [func trigger_reload] - [line_num 266] - C:\Users\é\Desktop\Python_django_diploma_dpo\backend\backend\urls.py changed, reloading.
[INFO] - [2023-07-01 13:36:41,658] - [file autoreload.py] - [module autoreload] - [func run_with_reloader] - [line_num 668] - Watching for file changes with StatReloader
[WARNING] - [2023-07-01 13:36:45,917] - [file log.py] - [module log] - [func log_response] - [line_num 241] - Not Found: /
[INFO] - [2023-07-01 13:39:31,007] - [file autoreload.py] - [module autoreload] - [func trigger_reload] - [line_num 266] - C:\Users\é\Desktop\Python_django_diploma_dpo\backend\api\urls.py changed, reloading.
[INFO] - [2023-07-01 13:39:31,702] - [file autoreload.py] - [module autoreload] - [func run_with_reloader] - [line_num 668] - Watching for file changes with StatReloader
[INFO] - [2023-07-01 13:39:42,392] - [file autoreload.py] - [module autoreload] - [func trigger_reload] - [line_num 266] - C:\Users\é\Desktop\Python_django_diploma_dpo\backend\api\urls.py changed, reloading.
[INFO] - [2023-07-01 13:39:42,987] - [file autoreload.py] - [module autoreload] - [func run_with_reloader] - [line_num 668] - Watching for file changes with StatReloader
[INFO] - [2023-07-01 13:39:52,536] - [file autoreload.py] - [module autoreload] - [func trigger_reload] - [line_num 266] - C:\Users\é\Desktop\Python_django_diploma_dpo\backend\api\urls.py changed, reloading.
[INFO] - [2023-07-01 13:39:53,313] - [file autoreload.py] - [module autoreload] - [func run_with_reloader] - [line_num 668] - Watching for file changes with StatReloader
[INFO] - [2023-07-01 13:40:02,035] - [file autoreload.py] - [module autoreload] - [func trigger_reload] - [line_num 266] - C:\Users\é\Desktop\Python_django_diploma_dpo\backend\api\urls.py changed, reloading.
[INFO] - [2023-07-01 13:40:02,631] - [file autoreload.py] - [module autoreload] - [func run_with_reloader] - [line_num 668] - Watching for file changes with StatReloader
[INFO] - [2023-07-01 13:40:13,342] - [file autoreload.py] - [module autoreload] - [func trigger_reload] - [line_num 266] - C:\Users\é\Desktop\Python_django_diploma_dpo\backend\api\urls.py changed, reloading.
[INFO] - [2023-07-01 13:40:13,891] - [file autoreload.py] - [module autoreload] - [func run_with_reloader] - [line_num 668] - Watching for file changes with StatReloader
[INFO] - [2023-07-01 17:41:03,891] - [file autoreload.py] - [module autoreload] - [func run_with_reloader] - [line_num 668] - Watching for file changes with StatReloader
[INFO] - [2023-07-01 17:41:19,982] - [file autoreload.py] - [module autoreload] - [func run_with_reloader] - [line_num 668] - Watching for file changes with StatReloader
[WARNING] - [2023-07-01 17:41:57,356] - [file log.py] - [module log] - [func log_response] - [line_num 241] - Not Found: /
[WARNING] - [2023-07-01 17:41:58,036] - [file log.py] - [module log] - [func log_response] - [line_num 241] - Not Found: /
[INFO] - [2023-07-01 17:48:22,216] - [file autoreload.py] - [module autoreload] - [func trigger_reload] - [line_num 266] - C:\Users\é\Desktop\Python_django_diploma_dpo\backend\frontend\__init__.py changed, reloading.
[INFO] - [2023-07-01 17:48:23,335] - [file autoreload.py] - [module autoreload] - [func run_with_reloader] - [line_num 668] - Watching for file changes with StatReloader
[WARNING] - [2023-07-01 17:48:27,910] - [file log.py] - [module log] - [func log_response] - [line_num 241] - Not Found: /
[WARNING] - [2023-07-01 17:48:28,650] - [file log.py] - [module log] - [func log_response] - [line_num 241] - Not Found: /
[INFO] - [2023-07-01 17:49:24,867] - [file autoreload.py] - [module autoreload] - [func trigger_reload] - [line_num 266] - C:\Users\é\Desktop\Python_django_diploma_dpo\backend\backend\urls.py changed, reloading.
[INFO] - [2023-07-01 17:49:25,408] - [file autoreload.py] - [module autoreload] - [func run_with_reloader] - [line_num 668] - Watching for file changes with StatReloader
[INFO] - [2023-07-01 17:49:43,082] - [file autoreload.py] - [module autoreload] - [func trigger_reload] - [line_num 266] - C:\Users\é\Desktop\Python_django_diploma_dpo\backend\backend\urls.py changed, reloading.
[INFO] - [2023-07-01 17:49:43,764] - [file autoreload.py] - [module autoreload] - [func run_with_reloader] - [line_num 668] - Watching for file changes with StatReloader
[ERROR] - [2023-07-01 17:51:56,095] - [file log.py] - [module log] - [func log_response] - [line_num 241] - Internal Server Error: /admin/login/
Traceback (most recent call last):
  File "C:\py\Lib\site-packages\django\db\backends\utils.py", line 89, in _execute
    return self.cursor.execute(sql, params)
           ^^^^^^^^^^^^^^^^^^^^^^^^^^^^^^^^
  File "C:\py\Lib\site-packages\django\db\backends\sqlite3\base.py", line 328, in execute
    return super().execute(query, params)
           ^^^^^^^^^^^^^^^^^^^^^^^^^^^^^^
sqlite3.OperationalError: no such table: auth_user

The above exception was the direct cause of the following exception:

Traceback (most recent call last):
  File "C:\py\Lib\site-packages\django\core\handlers\exception.py", line 55, in inner
    response = get_response(request)
               ^^^^^^^^^^^^^^^^^^^^^
  File "C:\py\Lib\site-packages\django\core\handlers\base.py", line 197, in _get_response
    response = wrapped_callback(request, *callback_args, **callback_kwargs)
               ^^^^^^^^^^^^^^^^^^^^^^^^^^^^^^^^^^^^^^^^^^^^^^^^^^^^^^^^^^^^
  File "C:\py\Lib\site-packages\django\utils\decorators.py", line 46, in _wrapper
    return bound_method(*args, **kwargs)
           ^^^^^^^^^^^^^^^^^^^^^^^^^^^^^
  File "C:\py\Lib\site-packages\django\views\decorators\cache.py", line 62, in _wrapper_view_func
    response = view_func(request, *args, **kwargs)
               ^^^^^^^^^^^^^^^^^^^^^^^^^^^^^^^^^^^
  File "C:\py\Lib\site-packages\django\contrib\admin\sites.py", line 441, in login
    return LoginView.as_view(**defaults)(request)
           ^^^^^^^^^^^^^^^^^^^^^^^^^^^^^^^^^^^^^^
  File "C:\py\Lib\site-packages\django\views\generic\base.py", line 104, in view
    return self.dispatch(request, *args, **kwargs)
           ^^^^^^^^^^^^^^^^^^^^^^^^^^^^^^^^^^^^^^^
  File "C:\py\Lib\site-packages\django\utils\decorators.py", line 46, in _wrapper
    return bound_method(*args, **kwargs)
           ^^^^^^^^^^^^^^^^^^^^^^^^^^^^^
  File "C:\py\Lib\site-packages\django\views\decorators\debug.py", line 92, in sensitive_post_parameters_wrapper
    return view(request, *args, **kwargs)
           ^^^^^^^^^^^^^^^^^^^^^^^^^^^^^^
  File "C:\py\Lib\site-packages\django\utils\decorators.py", line 46, in _wrapper
    return bound_method(*args, **kwargs)
           ^^^^^^^^^^^^^^^^^^^^^^^^^^^^^
  File "C:\py\Lib\site-packages\django\utils\decorators.py", line 134, in _wrapper_view
    response = view_func(request, *args, **kwargs)
               ^^^^^^^^^^^^^^^^^^^^^^^^^^^^^^^^^^^
  File "C:\py\Lib\site-packages\django\utils\decorators.py", line 46, in _wrapper
    return bound_method(*args, **kwargs)
           ^^^^^^^^^^^^^^^^^^^^^^^^^^^^^
  File "C:\py\Lib\site-packages\django\views\decorators\cache.py", line 62, in _wrapper_view_func
    response = view_func(request, *args, **kwargs)
               ^^^^^^^^^^^^^^^^^^^^^^^^^^^^^^^^^^^
  File "C:\py\Lib\site-packages\django\contrib\auth\views.py", line 90, in dispatch
    return super().dispatch(request, *args, **kwargs)
           ^^^^^^^^^^^^^^^^^^^^^^^^^^^^^^^^^^^^^^^^^^
  File "C:\py\Lib\site-packages\django\views\generic\base.py", line 143, in dispatch
    return handler(request, *args, **kwargs)
           ^^^^^^^^^^^^^^^^^^^^^^^^^^^^^^^^^
  File "C:\py\Lib\site-packages\django\views\generic\edit.py", line 152, in post
    if form.is_valid():
       ^^^^^^^^^^^^^^^
  File "C:\py\Lib\site-packages\django\forms\forms.py", line 201, in is_valid
    return self.is_bound and not self.errors
                                 ^^^^^^^^^^^
  File "C:\py\Lib\site-packages\django\forms\forms.py", line 196, in errors
    self.full_clean()
  File "C:\py\Lib\site-packages\django\forms\forms.py", line 434, in full_clean
    self._clean_form()
  File "C:\py\Lib\site-packages\django\forms\forms.py", line 455, in _clean_form
    cleaned_data = self.clean()
                   ^^^^^^^^^^^^
  File "C:\py\Lib\site-packages\django\contrib\auth\forms.py", line 242, in clean
    self.user_cache = authenticate(
                      ^^^^^^^^^^^^^
  File "C:\py\Lib\site-packages\django\views\decorators\debug.py", line 42, in sensitive_variables_wrapper
    return func(*func_args, **func_kwargs)
           ^^^^^^^^^^^^^^^^^^^^^^^^^^^^^^^
  File "C:\py\Lib\site-packages\django\contrib\auth\__init__.py", line 77, in authenticate
    user = backend.authenticate(request, **credentials)
           ^^^^^^^^^^^^^^^^^^^^^^^^^^^^^^^^^^^^^^^^^^^^
  File "C:\py\Lib\site-packages\django\contrib\auth\backends.py", line 46, in authenticate
    user = UserModel._default_manager.get_by_natural_key(username)
           ^^^^^^^^^^^^^^^^^^^^^^^^^^^^^^^^^^^^^^^^^^^^^^^^^^^^^^^
  File "C:\py\Lib\site-packages\django\contrib\auth\base_user.py", line 54, in get_by_natural_key
    return self.get(**{self.model.USERNAME_FIELD: username})
           ^^^^^^^^^^^^^^^^^^^^^^^^^^^^^^^^^^^^^^^^^^^^^^^^^
  File "C:\py\Lib\site-packages\django\db\models\manager.py", line 87, in manager_method
    return getattr(self.get_queryset(), name)(*args, **kwargs)
           ^^^^^^^^^^^^^^^^^^^^^^^^^^^^^^^^^^^^^^^^^^^^^^^^^^^
  File "C:\py\Lib\site-packages\django\db\models\query.py", line 633, in get
    num = len(clone)
          ^^^^^^^^^^
  File "C:\py\Lib\site-packages\django\db\models\query.py", line 380, in __len__
    self._fetch_all()
  File "C:\py\Lib\site-packages\django\db\models\query.py", line 1881, in _fetch_all
    self._result_cache = list(self._iterable_class(self))
                         ^^^^^^^^^^^^^^^^^^^^^^^^^^^^^^^^
  File "C:\py\Lib\site-packages\django\db\models\query.py", line 91, in __iter__
    results = compiler.execute_sql(
              ^^^^^^^^^^^^^^^^^^^^^
  File "C:\py\Lib\site-packages\django\db\models\sql\compiler.py", line 1562, in execute_sql
    cursor.execute(sql, params)
  File "C:\py\Lib\site-packages\django\db\backends\utils.py", line 102, in execute
    return super().execute(sql, params)
           ^^^^^^^^^^^^^^^^^^^^^^^^^^^^
  File "C:\py\Lib\site-packages\django\db\backends\utils.py", line 67, in execute
    return self._execute_with_wrappers(
           ^^^^^^^^^^^^^^^^^^^^^^^^^^^^
  File "C:\py\Lib\site-packages\django\db\backends\utils.py", line 80, in _execute_with_wrappers
    return executor(sql, params, many, context)
           ^^^^^^^^^^^^^^^^^^^^^^^^^^^^^^^^^^^^
  File "C:\py\Lib\site-packages\django\db\backends\utils.py", line 84, in _execute
    with self.db.wrap_database_errors:
  File "C:\py\Lib\site-packages\django\db\utils.py", line 91, in __exit__
    raise dj_exc_value.with_traceback(traceback) from exc_value
  File "C:\py\Lib\site-packages\django\db\backends\utils.py", line 89, in _execute
    return self.cursor.execute(sql, params)
           ^^^^^^^^^^^^^^^^^^^^^^^^^^^^^^^^
  File "C:\py\Lib\site-packages\django\db\backends\sqlite3\base.py", line 328, in execute
    return super().execute(query, params)
           ^^^^^^^^^^^^^^^^^^^^^^^^^^^^^^
django.db.utils.OperationalError: no such table: auth_user
[INFO] - [2023-07-01 18:06:01,129] - [file autoreload.py] - [module autoreload] - [func trigger_reload] - [line_num 266] - C:\Users\é\Desktop\Python_django_diploma_dpo\backend\backend\settings.py changed, reloading.
[INFO] - [2023-07-01 18:17:22,415] - [file autoreload.py] - [module autoreload] - [func run_with_reloader] - [line_num 668] - Watching for file changes with StatReloader
[INFO] - [2023-07-01 18:18:04,313] - [file autoreload.py] - [module autoreload] - [func trigger_reload] - [line_num 266] - C:\Users\é\Desktop\Python_django_diploma_dpo\backend\backend\settings.py changed, reloading.
[INFO] - [2023-07-01 18:18:04,782] - [file autoreload.py] - [module autoreload] - [func run_with_reloader] - [line_num 668] - Watching for file changes with StatReloader
[INFO] - [2023-07-01 18:18:14,291] - [file autoreload.py] - [module autoreload] - [func trigger_reload] - [line_num 266] - C:\Users\é\Desktop\Python_django_diploma_dpo\backend\backend\settings.py changed, reloading.
[INFO] - [2023-07-01 18:18:14,762] - [file autoreload.py] - [module autoreload] - [func run_with_reloader] - [line_num 668] - Watching for file changes with StatReloader
[INFO] - [2023-07-01 18:18:48,512] - [file autoreload.py] - [module autoreload] - [func trigger_reload] - [line_num 266] - C:\Users\é\Desktop\Python_django_diploma_dpo\backend\backend\settings.py changed, reloading.
[INFO] - [2023-07-01 18:18:48,853] - [file autoreload.py] - [module autoreload] - [func run_with_reloader] - [line_num 668] - Watching for file changes with StatReloader
[INFO] - [2023-07-01 18:18:54,259] - [file autoreload.py] - [module autoreload] - [func trigger_reload] - [line_num 266] - C:\Users\é\Desktop\Python_django_diploma_dpo\backend\backend\settings.py changed, reloading.
[INFO] - [2023-07-01 18:18:54,663] - [file autoreload.py] - [module autoreload] - [func run_with_reloader] - [line_num 668] - Watching for file changes with StatReloader
[INFO] - [2023-07-01 18:19:14,187] - [file autoreload.py] - [module autoreload] - [func run_with_reloader] - [line_num 668] - Watching for file changes with StatReloader
[INFO] - [2023-07-01 18:19:46,846] - [file autoreload.py] - [module autoreload] - [func trigger_reload] - [line_num 266] - C:\Users\é\Desktop\Python_django_diploma_dpo\backend\backend\settings.py changed, reloading.
[INFO] - [2023-07-01 18:19:47,538] - [file autoreload.py] - [module autoreload] - [func run_with_reloader] - [line_num 668] - Watching for file changes with StatReloader
[ERROR] - [2023-07-01 18:19:57,461] - [file log.py] - [module log] - [func log_response] - [line_num 241] - Internal Server Error: /api/products/limited/
Traceback (most recent call last):
  File "C:\py\Lib\site-packages\django\db\backends\utils.py", line 89, in _execute
    return self.cursor.execute(sql, params)
           ^^^^^^^^^^^^^^^^^^^^^^^^^^^^^^^^
  File "C:\py\Lib\site-packages\django\db\backends\sqlite3\base.py", line 328, in execute
    return super().execute(query, params)
           ^^^^^^^^^^^^^^^^^^^^^^^^^^^^^^
sqlite3.OperationalError: no such table: frontend_product

The above exception was the direct cause of the following exception:

Traceback (most recent call last):
  File "C:\py\Lib\site-packages\django\core\handlers\exception.py", line 55, in inner
    response = get_response(request)
               ^^^^^^^^^^^^^^^^^^^^^
  File "C:\py\Lib\site-packages\django\core\handlers\base.py", line 197, in _get_response
    response = wrapped_callback(request, *callback_args, **callback_kwargs)
               ^^^^^^^^^^^^^^^^^^^^^^^^^^^^^^^^^^^^^^^^^^^^^^^^^^^^^^^^^^^^
  File "C:\py\Lib\site-packages\django\views\decorators\csrf.py", line 56, in wrapper_view
    return view_func(*args, **kwargs)
           ^^^^^^^^^^^^^^^^^^^^^^^^^^
  File "C:\py\Lib\site-packages\django\views\generic\base.py", line 104, in view
    return self.dispatch(request, *args, **kwargs)
           ^^^^^^^^^^^^^^^^^^^^^^^^^^^^^^^^^^^^^^^
  File "C:\py\Lib\site-packages\rest_framework\views.py", line 509, in dispatch
    response = self.handle_exception(exc)
               ^^^^^^^^^^^^^^^^^^^^^^^^^^
  File "C:\py\Lib\site-packages\rest_framework\views.py", line 469, in handle_exception
    self.raise_uncaught_exception(exc)
  File "C:\py\Lib\site-packages\rest_framework\views.py", line 480, in raise_uncaught_exception
    raise exc
  File "C:\py\Lib\site-packages\rest_framework\views.py", line 506, in dispatch
    response = handler(request, *args, **kwargs)
               ^^^^^^^^^^^^^^^^^^^^^^^^^^^^^^^^^
  File "C:\Users\é\Desktop\Python_django_diploma_dpo\backend\api\views\LimitedProductAPIView.py", line 21, in get
    a = super().get(request, *args, **kwargs)
        ^^^^^^^^^^^^^^^^^^^^^^^^^^^^^^^^^^^^^
  File "C:\py\Lib\site-packages\rest_framework\generics.py", line 199, in get
    return self.list(request, *args, **kwargs)
           ^^^^^^^^^^^^^^^^^^^^^^^^^^^^^^^^^^^
  File "C:\py\Lib\site-packages\rest_framework\mixins.py", line 40, in list
    page = self.paginate_queryset(queryset)
           ^^^^^^^^^^^^^^^^^^^^^^^^^^^^^^^^
  File "C:\py\Lib\site-packages\rest_framework\generics.py", line 171, in paginate_queryset
    return self.paginator.paginate_queryset(queryset, self.request, view=self)
           ^^^^^^^^^^^^^^^^^^^^^^^^^^^^^^^^^^^^^^^^^^^^^^^^^^^^^^^^^^^^^^^^^^^
  File "C:\py\Lib\site-packages\rest_framework\pagination.py", line 387, in paginate_queryset
    self.count = self.get_count(queryset)
                 ^^^^^^^^^^^^^^^^^^^^^^^^
  File "C:\py\Lib\site-packages\rest_framework\pagination.py", line 525, in get_count
    return queryset.count()
           ^^^^^^^^^^^^^^^^
  File "C:\py\Lib\site-packages\django\db\models\query.py", line 608, in count
    return self.query.get_count(using=self.db)
           ^^^^^^^^^^^^^^^^^^^^^^^^^^^^^^^^^^^
  File "C:\py\Lib\site-packages\django\db\models\sql\query.py", line 557, in get_count
    return obj.get_aggregation(using, {"__count": Count("*")})["__count"]
           ^^^^^^^^^^^^^^^^^^^^^^^^^^^^^^^^^^^^^^^^^^^^^^^^^^^
  File "C:\py\Lib\site-packages\django\db\models\sql\query.py", line 543, in get_aggregation
    result = compiler.execute_sql(SINGLE)
             ^^^^^^^^^^^^^^^^^^^^^^^^^^^^
  File "C:\py\Lib\site-packages\django\db\models\sql\compiler.py", line 1562, in execute_sql
    cursor.execute(sql, params)
  File "C:\py\Lib\site-packages\django\db\backends\utils.py", line 102, in execute
    return super().execute(sql, params)
           ^^^^^^^^^^^^^^^^^^^^^^^^^^^^
  File "C:\py\Lib\site-packages\django\db\backends\utils.py", line 67, in execute
    return self._execute_with_wrappers(
           ^^^^^^^^^^^^^^^^^^^^^^^^^^^^
  File "C:\py\Lib\site-packages\django\db\backends\utils.py", line 80, in _execute_with_wrappers
    return executor(sql, params, many, context)
           ^^^^^^^^^^^^^^^^^^^^^^^^^^^^^^^^^^^^
  File "C:\py\Lib\site-packages\django\db\backends\utils.py", line 84, in _execute
    with self.db.wrap_database_errors:
  File "C:\py\Lib\site-packages\django\db\utils.py", line 91, in __exit__
    raise dj_exc_value.with_traceback(traceback) from exc_value
  File "C:\py\Lib\site-packages\django\db\backends\utils.py", line 89, in _execute
    return self.cursor.execute(sql, params)
           ^^^^^^^^^^^^^^^^^^^^^^^^^^^^^^^^
  File "C:\py\Lib\site-packages\django\db\backends\sqlite3\base.py", line 328, in execute
    return super().execute(query, params)
           ^^^^^^^^^^^^^^^^^^^^^^^^^^^^^^
django.db.utils.OperationalError: no such table: frontend_product
[ERROR] - [2023-07-01 18:19:57,540] - [file log.py] - [module log] - [func log_response] - [line_num 241] - Internal Server Error: /api/products/popular/
Traceback (most recent call last):
  File "C:\py\Lib\site-packages\django\db\backends\utils.py", line 89, in _execute
    return self.cursor.execute(sql, params)
           ^^^^^^^^^^^^^^^^^^^^^^^^^^^^^^^^
  File "C:\py\Lib\site-packages\django\db\backends\sqlite3\base.py", line 328, in execute
    return super().execute(query, params)
           ^^^^^^^^^^^^^^^^^^^^^^^^^^^^^^
sqlite3.OperationalError: no such table: frontend_product

The above exception was the direct cause of the following exception:

Traceback (most recent call last):
  File "C:\py\Lib\site-packages\django\core\handlers\exception.py", line 55, in inner
    response = get_response(request)
               ^^^^^^^^^^^^^^^^^^^^^
  File "C:\py\Lib\site-packages\django\core\handlers\base.py", line 197, in _get_response
    response = wrapped_callback(request, *callback_args, **callback_kwargs)
               ^^^^^^^^^^^^^^^^^^^^^^^^^^^^^^^^^^^^^^^^^^^^^^^^^^^^^^^^^^^^
  File "C:\py\Lib\site-packages\django\views\decorators\csrf.py", line 56, in wrapper_view
    return view_func(*args, **kwargs)
           ^^^^^^^^^^^^^^^^^^^^^^^^^^
  File "C:\py\Lib\site-packages\django\views\generic\base.py", line 104, in view
    return self.dispatch(request, *args, **kwargs)
           ^^^^^^^^^^^^^^^^^^^^^^^^^^^^^^^^^^^^^^^
  File "C:\py\Lib\site-packages\rest_framework\views.py", line 509, in dispatch
    response = self.handle_exception(exc)
               ^^^^^^^^^^^^^^^^^^^^^^^^^^
  File "C:\py\Lib\site-packages\rest_framework\views.py", line 469, in handle_exception
    self.raise_uncaught_exception(exc)
  File "C:\py\Lib\site-packages\rest_framework\views.py", line 480, in raise_uncaught_exception
    raise exc
  File "C:\py\Lib\site-packages\rest_framework\views.py", line 506, in dispatch
    response = handler(request, *args, **kwargs)
               ^^^^^^^^^^^^^^^^^^^^^^^^^^^^^^^^^
  File "C:\Users\é\Desktop\Python_django_diploma_dpo\backend\api\views\PopularProductAPIView.py", line 23, in get
    a = super().get(request, *args, **kwargs)
        ^^^^^^^^^^^^^^^^^^^^^^^^^^^^^^^^^^^^^
  File "C:\py\Lib\site-packages\rest_framework\generics.py", line 199, in get
    return self.list(request, *args, **kwargs)
           ^^^^^^^^^^^^^^^^^^^^^^^^^^^^^^^^^^^
  File "C:\py\Lib\site-packages\rest_framework\mixins.py", line 40, in list
    page = self.paginate_queryset(queryset)
           ^^^^^^^^^^^^^^^^^^^^^^^^^^^^^^^^
  File "C:\py\Lib\site-packages\rest_framework\generics.py", line 171, in paginate_queryset
    return self.paginator.paginate_queryset(queryset, self.request, view=self)
           ^^^^^^^^^^^^^^^^^^^^^^^^^^^^^^^^^^^^^^^^^^^^^^^^^^^^^^^^^^^^^^^^^^^
  File "C:\py\Lib\site-packages\rest_framework\pagination.py", line 387, in paginate_queryset
    self.count = self.get_count(queryset)
                 ^^^^^^^^^^^^^^^^^^^^^^^^
  File "C:\py\Lib\site-packages\rest_framework\pagination.py", line 525, in get_count
    return queryset.count()
           ^^^^^^^^^^^^^^^^
  File "C:\py\Lib\site-packages\django\db\models\query.py", line 608, in count
    return self.query.get_count(using=self.db)
           ^^^^^^^^^^^^^^^^^^^^^^^^^^^^^^^^^^^
  File "C:\py\Lib\site-packages\django\db\models\sql\query.py", line 557, in get_count
    return obj.get_aggregation(using, {"__count": Count("*")})["__count"]
           ^^^^^^^^^^^^^^^^^^^^^^^^^^^^^^^^^^^^^^^^^^^^^^^^^^^
  File "C:\py\Lib\site-packages\django\db\models\sql\query.py", line 543, in get_aggregation
    result = compiler.execute_sql(SINGLE)
             ^^^^^^^^^^^^^^^^^^^^^^^^^^^^
  File "C:\py\Lib\site-packages\django\db\models\sql\compiler.py", line 1562, in execute_sql
    cursor.execute(sql, params)
  File "C:\py\Lib\site-packages\django\db\backends\utils.py", line 102, in execute
    return super().execute(sql, params)
           ^^^^^^^^^^^^^^^^^^^^^^^^^^^^
  File "C:\py\Lib\site-packages\django\db\backends\utils.py", line 67, in execute
    return self._execute_with_wrappers(
           ^^^^^^^^^^^^^^^^^^^^^^^^^^^^
  File "C:\py\Lib\site-packages\django\db\backends\utils.py", line 80, in _execute_with_wrappers
    return executor(sql, params, many, context)
           ^^^^^^^^^^^^^^^^^^^^^^^^^^^^^^^^^^^^
  File "C:\py\Lib\site-packages\django\db\backends\utils.py", line 84, in _execute
    with self.db.wrap_database_errors:
  File "C:\py\Lib\site-packages\django\db\utils.py", line 91, in __exit__
    raise dj_exc_value.with_traceback(traceback) from exc_value
  File "C:\py\Lib\site-packages\django\db\backends\utils.py", line 89, in _execute
    return self.cursor.execute(sql, params)
           ^^^^^^^^^^^^^^^^^^^^^^^^^^^^^^^^
  File "C:\py\Lib\site-packages\django\db\backends\sqlite3\base.py", line 328, in execute
    return super().execute(query, params)
           ^^^^^^^^^^^^^^^^^^^^^^^^^^^^^^
django.db.utils.OperationalError: no such table: frontend_product
[ERROR] - [2023-07-01 18:19:57,652] - [file log.py] - [module log] - [func log_response] - [line_num 241] - Internal Server Error: /api/products/limited/
Traceback (most recent call last):
  File "C:\py\Lib\site-packages\django\db\backends\utils.py", line 89, in _execute
    return self.cursor.execute(sql, params)
           ^^^^^^^^^^^^^^^^^^^^^^^^^^^^^^^^
  File "C:\py\Lib\site-packages\django\db\backends\sqlite3\base.py", line 328, in execute
    return super().execute(query, params)
           ^^^^^^^^^^^^^^^^^^^^^^^^^^^^^^
sqlite3.OperationalError: no such table: frontend_product

The above exception was the direct cause of the following exception:

Traceback (most recent call last):
  File "C:\py\Lib\site-packages\django\core\handlers\exception.py", line 55, in inner
    response = get_response(request)
               ^^^^^^^^^^^^^^^^^^^^^
  File "C:\py\Lib\site-packages\django\core\handlers\base.py", line 197, in _get_response
    response = wrapped_callback(request, *callback_args, **callback_kwargs)
               ^^^^^^^^^^^^^^^^^^^^^^^^^^^^^^^^^^^^^^^^^^^^^^^^^^^^^^^^^^^^
  File "C:\py\Lib\site-packages\django\views\decorators\csrf.py", line 56, in wrapper_view
    return view_func(*args, **kwargs)
           ^^^^^^^^^^^^^^^^^^^^^^^^^^
  File "C:\py\Lib\site-packages\django\views\generic\base.py", line 104, in view
    return self.dispatch(request, *args, **kwargs)
           ^^^^^^^^^^^^^^^^^^^^^^^^^^^^^^^^^^^^^^^
  File "C:\py\Lib\site-packages\rest_framework\views.py", line 509, in dispatch
    response = self.handle_exception(exc)
               ^^^^^^^^^^^^^^^^^^^^^^^^^^
  File "C:\py\Lib\site-packages\rest_framework\views.py", line 469, in handle_exception
    self.raise_uncaught_exception(exc)
  File "C:\py\Lib\site-packages\rest_framework\views.py", line 480, in raise_uncaught_exception
    raise exc
  File "C:\py\Lib\site-packages\rest_framework\views.py", line 506, in dispatch
    response = handler(request, *args, **kwargs)
               ^^^^^^^^^^^^^^^^^^^^^^^^^^^^^^^^^
  File "C:\Users\é\Desktop\Python_django_diploma_dpo\backend\api\views\LimitedProductAPIView.py", line 21, in get
    a = super().get(request, *args, **kwargs)
        ^^^^^^^^^^^^^^^^^^^^^^^^^^^^^^^^^^^^^
  File "C:\py\Lib\site-packages\rest_framework\generics.py", line 199, in get
    return self.list(request, *args, **kwargs)
           ^^^^^^^^^^^^^^^^^^^^^^^^^^^^^^^^^^^
  File "C:\py\Lib\site-packages\rest_framework\mixins.py", line 40, in list
    page = self.paginate_queryset(queryset)
           ^^^^^^^^^^^^^^^^^^^^^^^^^^^^^^^^
  File "C:\py\Lib\site-packages\rest_framework\generics.py", line 171, in paginate_queryset
    return self.paginator.paginate_queryset(queryset, self.request, view=self)
           ^^^^^^^^^^^^^^^^^^^^^^^^^^^^^^^^^^^^^^^^^^^^^^^^^^^^^^^^^^^^^^^^^^^
  File "C:\py\Lib\site-packages\rest_framework\pagination.py", line 387, in paginate_queryset
    self.count = self.get_count(queryset)
                 ^^^^^^^^^^^^^^^^^^^^^^^^
  File "C:\py\Lib\site-packages\rest_framework\pagination.py", line 525, in get_count
    return queryset.count()
           ^^^^^^^^^^^^^^^^
  File "C:\py\Lib\site-packages\django\db\models\query.py", line 608, in count
    return self.query.get_count(using=self.db)
           ^^^^^^^^^^^^^^^^^^^^^^^^^^^^^^^^^^^
  File "C:\py\Lib\site-packages\django\db\models\sql\query.py", line 557, in get_count
    return obj.get_aggregation(using, {"__count": Count("*")})["__count"]
           ^^^^^^^^^^^^^^^^^^^^^^^^^^^^^^^^^^^^^^^^^^^^^^^^^^^
  File "C:\py\Lib\site-packages\django\db\models\sql\query.py", line 543, in get_aggregation
    result = compiler.execute_sql(SINGLE)
             ^^^^^^^^^^^^^^^^^^^^^^^^^^^^
  File "C:\py\Lib\site-packages\django\db\models\sql\compiler.py", line 1562, in execute_sql
    cursor.execute(sql, params)
  File "C:\py\Lib\site-packages\django\db\backends\utils.py", line 102, in execute
    return super().execute(sql, params)
           ^^^^^^^^^^^^^^^^^^^^^^^^^^^^
  File "C:\py\Lib\site-packages\django\db\backends\utils.py", line 67, in execute
    return self._execute_with_wrappers(
           ^^^^^^^^^^^^^^^^^^^^^^^^^^^^
  File "C:\py\Lib\site-packages\django\db\backends\utils.py", line 80, in _execute_with_wrappers
    return executor(sql, params, many, context)
           ^^^^^^^^^^^^^^^^^^^^^^^^^^^^^^^^^^^^
  File "C:\py\Lib\site-packages\django\db\backends\utils.py", line 84, in _execute
    with self.db.wrap_database_errors:
  File "C:\py\Lib\site-packages\django\db\utils.py", line 91, in __exit__
    raise dj_exc_value.with_traceback(traceback) from exc_value
  File "C:\py\Lib\site-packages\django\db\backends\utils.py", line 89, in _execute
    return self.cursor.execute(sql, params)
           ^^^^^^^^^^^^^^^^^^^^^^^^^^^^^^^^
  File "C:\py\Lib\site-packages\django\db\backends\sqlite3\base.py", line 328, in execute
    return super().execute(query, params)
           ^^^^^^^^^^^^^^^^^^^^^^^^^^^^^^
django.db.utils.OperationalError: no such table: frontend_product
[ERROR] - [2023-07-01 18:19:57,676] - [file log.py] - [module log] - [func log_response] - [line_num 241] - Internal Server Error: /api/banners/
Traceback (most recent call last):
  File "C:\py\Lib\site-packages\django\db\backends\utils.py", line 89, in _execute
    return self.cursor.execute(sql, params)
           ^^^^^^^^^^^^^^^^^^^^^^^^^^^^^^^^
  File "C:\py\Lib\site-packages\django\db\backends\sqlite3\base.py", line 328, in execute
    return super().execute(query, params)
           ^^^^^^^^^^^^^^^^^^^^^^^^^^^^^^
sqlite3.OperationalError: no such table: frontend_product

The above exception was the direct cause of the following exception:

Traceback (most recent call last):
  File "C:\py\Lib\site-packages\django\core\handlers\exception.py", line 55, in inner
    response = get_response(request)
               ^^^^^^^^^^^^^^^^^^^^^
  File "C:\py\Lib\site-packages\django\core\handlers\base.py", line 197, in _get_response
    response = wrapped_callback(request, *callback_args, **callback_kwargs)
               ^^^^^^^^^^^^^^^^^^^^^^^^^^^^^^^^^^^^^^^^^^^^^^^^^^^^^^^^^^^^
  File "C:\py\Lib\site-packages\django\views\decorators\csrf.py", line 56, in wrapper_view
    return view_func(*args, **kwargs)
           ^^^^^^^^^^^^^^^^^^^^^^^^^^
  File "C:\py\Lib\site-packages\django\views\generic\base.py", line 104, in view
    return self.dispatch(request, *args, **kwargs)
           ^^^^^^^^^^^^^^^^^^^^^^^^^^^^^^^^^^^^^^^
  File "C:\py\Lib\site-packages\rest_framework\views.py", line 509, in dispatch
    response = self.handle_exception(exc)
               ^^^^^^^^^^^^^^^^^^^^^^^^^^
  File "C:\py\Lib\site-packages\rest_framework\views.py", line 469, in handle_exception
    self.raise_uncaught_exception(exc)
  File "C:\py\Lib\site-packages\rest_framework\views.py", line 480, in raise_uncaught_exception
    raise exc
  File "C:\py\Lib\site-packages\rest_framework\views.py", line 506, in dispatch
    response = handler(request, *args, **kwargs)
               ^^^^^^^^^^^^^^^^^^^^^^^^^^^^^^^^^
  File "C:\Users\é\Desktop\Python_django_diploma_dpo\backend\api\views\BannersAPIView.py", line 19, in get
    a = super().get(request, *args, **kwargs)
        ^^^^^^^^^^^^^^^^^^^^^^^^^^^^^^^^^^^^^
  File "C:\py\Lib\site-packages\rest_framework\generics.py", line 199, in get
    return self.list(request, *args, **kwargs)
           ^^^^^^^^^^^^^^^^^^^^^^^^^^^^^^^^^^^
  File "C:\py\Lib\site-packages\rest_framework\mixins.py", line 40, in list
    page = self.paginate_queryset(queryset)
           ^^^^^^^^^^^^^^^^^^^^^^^^^^^^^^^^
  File "C:\py\Lib\site-packages\rest_framework\generics.py", line 171, in paginate_queryset
    return self.paginator.paginate_queryset(queryset, self.request, view=self)
           ^^^^^^^^^^^^^^^^^^^^^^^^^^^^^^^^^^^^^^^^^^^^^^^^^^^^^^^^^^^^^^^^^^^
  File "C:\py\Lib\site-packages\rest_framework\pagination.py", line 387, in paginate_queryset
    self.count = self.get_count(queryset)
                 ^^^^^^^^^^^^^^^^^^^^^^^^
  File "C:\py\Lib\site-packages\rest_framework\pagination.py", line 525, in get_count
    return queryset.count()
           ^^^^^^^^^^^^^^^^
  File "C:\py\Lib\site-packages\django\db\models\query.py", line 608, in count
    return self.query.get_count(using=self.db)
           ^^^^^^^^^^^^^^^^^^^^^^^^^^^^^^^^^^^
  File "C:\py\Lib\site-packages\django\db\models\sql\query.py", line 557, in get_count
    return obj.get_aggregation(using, {"__count": Count("*")})["__count"]
           ^^^^^^^^^^^^^^^^^^^^^^^^^^^^^^^^^^^^^^^^^^^^^^^^^^^
  File "C:\py\Lib\site-packages\django\db\models\sql\query.py", line 543, in get_aggregation
    result = compiler.execute_sql(SINGLE)
             ^^^^^^^^^^^^^^^^^^^^^^^^^^^^
  File "C:\py\Lib\site-packages\django\db\models\sql\compiler.py", line 1562, in execute_sql
    cursor.execute(sql, params)
  File "C:\py\Lib\site-packages\django\db\backends\utils.py", line 102, in execute
    return super().execute(sql, params)
           ^^^^^^^^^^^^^^^^^^^^^^^^^^^^
  File "C:\py\Lib\site-packages\django\db\backends\utils.py", line 67, in execute
    return self._execute_with_wrappers(
           ^^^^^^^^^^^^^^^^^^^^^^^^^^^^
  File "C:\py\Lib\site-packages\django\db\backends\utils.py", line 80, in _execute_with_wrappers
    return executor(sql, params, many, context)
           ^^^^^^^^^^^^^^^^^^^^^^^^^^^^^^^^^^^^
  File "C:\py\Lib\site-packages\django\db\backends\utils.py", line 84, in _execute
    with self.db.wrap_database_errors:
  File "C:\py\Lib\site-packages\django\db\utils.py", line 91, in __exit__
    raise dj_exc_value.with_traceback(traceback) from exc_value
  File "C:\py\Lib\site-packages\django\db\backends\utils.py", line 89, in _execute
    return self.cursor.execute(sql, params)
           ^^^^^^^^^^^^^^^^^^^^^^^^^^^^^^^^
  File "C:\py\Lib\site-packages\django\db\backends\sqlite3\base.py", line 328, in execute
    return super().execute(query, params)
           ^^^^^^^^^^^^^^^^^^^^^^^^^^^^^^
django.db.utils.OperationalError: no such table: frontend_product
[ERROR] - [2023-07-01 18:19:57,692] - [file log.py] - [module log] - [func log_response] - [line_num 241] - Internal Server Error: /api/categories/
Traceback (most recent call last):
  File "C:\py\Lib\site-packages\django\db\backends\utils.py", line 89, in _execute
    return self.cursor.execute(sql, params)
           ^^^^^^^^^^^^^^^^^^^^^^^^^^^^^^^^
  File "C:\py\Lib\site-packages\django\db\backends\sqlite3\base.py", line 328, in execute
    return super().execute(query, params)
           ^^^^^^^^^^^^^^^^^^^^^^^^^^^^^^
sqlite3.OperationalError: no such table: frontend_category

The above exception was the direct cause of the following exception:

Traceback (most recent call last):
  File "C:\py\Lib\site-packages\django\core\handlers\exception.py", line 55, in inner
    response = get_response(request)
               ^^^^^^^^^^^^^^^^^^^^^
  File "C:\py\Lib\site-packages\django\core\handlers\base.py", line 197, in _get_response
    response = wrapped_callback(request, *callback_args, **callback_kwargs)
               ^^^^^^^^^^^^^^^^^^^^^^^^^^^^^^^^^^^^^^^^^^^^^^^^^^^^^^^^^^^^
  File "C:\py\Lib\site-packages\django\views\decorators\csrf.py", line 56, in wrapper_view
    return view_func(*args, **kwargs)
           ^^^^^^^^^^^^^^^^^^^^^^^^^^
  File "C:\py\Lib\site-packages\django\views\generic\base.py", line 104, in view
    return self.dispatch(request, *args, **kwargs)
           ^^^^^^^^^^^^^^^^^^^^^^^^^^^^^^^^^^^^^^^
  File "C:\py\Lib\site-packages\rest_framework\views.py", line 509, in dispatch
    response = self.handle_exception(exc)
               ^^^^^^^^^^^^^^^^^^^^^^^^^^
  File "C:\py\Lib\site-packages\rest_framework\views.py", line 469, in handle_exception
    self.raise_uncaught_exception(exc)
  File "C:\py\Lib\site-packages\rest_framework\views.py", line 480, in raise_uncaught_exception
    raise exc
  File "C:\py\Lib\site-packages\rest_framework\views.py", line 506, in dispatch
    response = handler(request, *args, **kwargs)
               ^^^^^^^^^^^^^^^^^^^^^^^^^^^^^^^^^
  File "C:\Users\é\Desktop\Python_django_diploma_dpo\backend\api\views\CategoriesAPIView.py", line 19, in get
    a = super().get(request, *args, **kwargs)
        ^^^^^^^^^^^^^^^^^^^^^^^^^^^^^^^^^^^^^
  File "C:\py\Lib\site-packages\rest_framework\generics.py", line 199, in get
    return self.list(request, *args, **kwargs)
           ^^^^^^^^^^^^^^^^^^^^^^^^^^^^^^^^^^^
  File "C:\py\Lib\site-packages\rest_framework\mixins.py", line 40, in list
    page = self.paginate_queryset(queryset)
           ^^^^^^^^^^^^^^^^^^^^^^^^^^^^^^^^
  File "C:\py\Lib\site-packages\rest_framework\generics.py", line 171, in paginate_queryset
    return self.paginator.paginate_queryset(queryset, self.request, view=self)
           ^^^^^^^^^^^^^^^^^^^^^^^^^^^^^^^^^^^^^^^^^^^^^^^^^^^^^^^^^^^^^^^^^^^
  File "C:\py\Lib\site-packages\rest_framework\pagination.py", line 387, in paginate_queryset
    self.count = self.get_count(queryset)
                 ^^^^^^^^^^^^^^^^^^^^^^^^
  File "C:\py\Lib\site-packages\rest_framework\pagination.py", line 525, in get_count
    return queryset.count()
           ^^^^^^^^^^^^^^^^
  File "C:\py\Lib\site-packages\django\db\models\query.py", line 608, in count
    return self.query.get_count(using=self.db)
           ^^^^^^^^^^^^^^^^^^^^^^^^^^^^^^^^^^^
  File "C:\py\Lib\site-packages\django\db\models\sql\query.py", line 557, in get_count
    return obj.get_aggregation(using, {"__count": Count("*")})["__count"]
           ^^^^^^^^^^^^^^^^^^^^^^^^^^^^^^^^^^^^^^^^^^^^^^^^^^^
  File "C:\py\Lib\site-packages\django\db\models\sql\query.py", line 543, in get_aggregation
    result = compiler.execute_sql(SINGLE)
             ^^^^^^^^^^^^^^^^^^^^^^^^^^^^
  File "C:\py\Lib\site-packages\django\db\models\sql\compiler.py", line 1562, in execute_sql
    cursor.execute(sql, params)
  File "C:\py\Lib\site-packages\django\db\backends\utils.py", line 102, in execute
    return super().execute(sql, params)
           ^^^^^^^^^^^^^^^^^^^^^^^^^^^^
  File "C:\py\Lib\site-packages\django\db\backends\utils.py", line 67, in execute
    return self._execute_with_wrappers(
           ^^^^^^^^^^^^^^^^^^^^^^^^^^^^
  File "C:\py\Lib\site-packages\django\db\backends\utils.py", line 80, in _execute_with_wrappers
    return executor(sql, params, many, context)
           ^^^^^^^^^^^^^^^^^^^^^^^^^^^^^^^^^^^^
  File "C:\py\Lib\site-packages\django\db\backends\utils.py", line 84, in _execute
    with self.db.wrap_database_errors:
  File "C:\py\Lib\site-packages\django\db\utils.py", line 91, in __exit__
    raise dj_exc_value.with_traceback(traceback) from exc_value
  File "C:\py\Lib\site-packages\django\db\backends\utils.py", line 89, in _execute
    return self.cursor.execute(sql, params)
           ^^^^^^^^^^^^^^^^^^^^^^^^^^^^^^^^
  File "C:\py\Lib\site-packages\django\db\backends\sqlite3\base.py", line 328, in execute
    return super().execute(query, params)
           ^^^^^^^^^^^^^^^^^^^^^^^^^^^^^^
django.db.utils.OperationalError: no such table: frontend_category
[ERROR] - [2023-07-01 18:20:07,453] - [file log.py] - [module log] - [func log_response] - [line_num 241] - Internal Server Error: /api/categories/
Traceback (most recent call last):
  File "C:\py\Lib\site-packages\django\db\backends\utils.py", line 89, in _execute
    return self.cursor.execute(sql, params)
           ^^^^^^^^^^^^^^^^^^^^^^^^^^^^^^^^
  File "C:\py\Lib\site-packages\django\db\backends\sqlite3\base.py", line 328, in execute
    return super().execute(query, params)
           ^^^^^^^^^^^^^^^^^^^^^^^^^^^^^^
sqlite3.OperationalError: no such table: frontend_category

The above exception was the direct cause of the following exception:

Traceback (most recent call last):
  File "C:\py\Lib\site-packages\django\core\handlers\exception.py", line 55, in inner
    response = get_response(request)
               ^^^^^^^^^^^^^^^^^^^^^
  File "C:\py\Lib\site-packages\django\core\handlers\base.py", line 197, in _get_response
    response = wrapped_callback(request, *callback_args, **callback_kwargs)
               ^^^^^^^^^^^^^^^^^^^^^^^^^^^^^^^^^^^^^^^^^^^^^^^^^^^^^^^^^^^^
  File "C:\py\Lib\site-packages\django\views\decorators\csrf.py", line 56, in wrapper_view
    return view_func(*args, **kwargs)
           ^^^^^^^^^^^^^^^^^^^^^^^^^^
  File "C:\py\Lib\site-packages\django\views\generic\base.py", line 104, in view
    return self.dispatch(request, *args, **kwargs)
           ^^^^^^^^^^^^^^^^^^^^^^^^^^^^^^^^^^^^^^^
  File "C:\py\Lib\site-packages\rest_framework\views.py", line 509, in dispatch
    response = self.handle_exception(exc)
               ^^^^^^^^^^^^^^^^^^^^^^^^^^
  File "C:\py\Lib\site-packages\rest_framework\views.py", line 469, in handle_exception
    self.raise_uncaught_exception(exc)
  File "C:\py\Lib\site-packages\rest_framework\views.py", line 480, in raise_uncaught_exception
    raise exc
  File "C:\py\Lib\site-packages\rest_framework\views.py", line 506, in dispatch
    response = handler(request, *args, **kwargs)
               ^^^^^^^^^^^^^^^^^^^^^^^^^^^^^^^^^
  File "C:\Users\é\Desktop\Python_django_diploma_dpo\backend\api\views\CategoriesAPIView.py", line 19, in get
    a = super().get(request, *args, **kwargs)
        ^^^^^^^^^^^^^^^^^^^^^^^^^^^^^^^^^^^^^
  File "C:\py\Lib\site-packages\rest_framework\generics.py", line 199, in get
    return self.list(request, *args, **kwargs)
           ^^^^^^^^^^^^^^^^^^^^^^^^^^^^^^^^^^^
  File "C:\py\Lib\site-packages\rest_framework\mixins.py", line 40, in list
    page = self.paginate_queryset(queryset)
           ^^^^^^^^^^^^^^^^^^^^^^^^^^^^^^^^
  File "C:\py\Lib\site-packages\rest_framework\generics.py", line 171, in paginate_queryset
    return self.paginator.paginate_queryset(queryset, self.request, view=self)
           ^^^^^^^^^^^^^^^^^^^^^^^^^^^^^^^^^^^^^^^^^^^^^^^^^^^^^^^^^^^^^^^^^^^
  File "C:\py\Lib\site-packages\rest_framework\pagination.py", line 387, in paginate_queryset
    self.count = self.get_count(queryset)
                 ^^^^^^^^^^^^^^^^^^^^^^^^
  File "C:\py\Lib\site-packages\rest_framework\pagination.py", line 525, in get_count
    return queryset.count()
           ^^^^^^^^^^^^^^^^
  File "C:\py\Lib\site-packages\django\db\models\query.py", line 608, in count
    return self.query.get_count(using=self.db)
           ^^^^^^^^^^^^^^^^^^^^^^^^^^^^^^^^^^^
  File "C:\py\Lib\site-packages\django\db\models\sql\query.py", line 557, in get_count
    return obj.get_aggregation(using, {"__count": Count("*")})["__count"]
           ^^^^^^^^^^^^^^^^^^^^^^^^^^^^^^^^^^^^^^^^^^^^^^^^^^^
  File "C:\py\Lib\site-packages\django\db\models\sql\query.py", line 543, in get_aggregation
    result = compiler.execute_sql(SINGLE)
             ^^^^^^^^^^^^^^^^^^^^^^^^^^^^
  File "C:\py\Lib\site-packages\django\db\models\sql\compiler.py", line 1562, in execute_sql
    cursor.execute(sql, params)
  File "C:\py\Lib\site-packages\django\db\backends\utils.py", line 102, in execute
    return super().execute(sql, params)
           ^^^^^^^^^^^^^^^^^^^^^^^^^^^^
  File "C:\py\Lib\site-packages\django\db\backends\utils.py", line 67, in execute
    return self._execute_with_wrappers(
           ^^^^^^^^^^^^^^^^^^^^^^^^^^^^
  File "C:\py\Lib\site-packages\django\db\backends\utils.py", line 80, in _execute_with_wrappers
    return executor(sql, params, many, context)
           ^^^^^^^^^^^^^^^^^^^^^^^^^^^^^^^^^^^^
  File "C:\py\Lib\site-packages\django\db\backends\utils.py", line 84, in _execute
    with self.db.wrap_database_errors:
  File "C:\py\Lib\site-packages\django\db\utils.py", line 91, in __exit__
    raise dj_exc_value.with_traceback(traceback) from exc_value
  File "C:\py\Lib\site-packages\django\db\backends\utils.py", line 89, in _execute
    return self.cursor.execute(sql, params)
           ^^^^^^^^^^^^^^^^^^^^^^^^^^^^^^^^
  File "C:\py\Lib\site-packages\django\db\backends\sqlite3\base.py", line 328, in execute
    return super().execute(query, params)
           ^^^^^^^^^^^^^^^^^^^^^^^^^^^^^^
django.db.utils.OperationalError: no such table: frontend_category
[ERROR] - [2023-07-01 18:20:07,472] - [file log.py] - [module log] - [func log_response] - [line_num 241] - Internal Server Error: /api/tags/
Traceback (most recent call last):
  File "C:\py\Lib\site-packages\django\db\backends\utils.py", line 89, in _execute
    return self.cursor.execute(sql, params)
           ^^^^^^^^^^^^^^^^^^^^^^^^^^^^^^^^
  File "C:\py\Lib\site-packages\django\db\backends\sqlite3\base.py", line 328, in execute
    return super().execute(query, params)
           ^^^^^^^^^^^^^^^^^^^^^^^^^^^^^^
sqlite3.OperationalError: no such table: frontend_tag

The above exception was the direct cause of the following exception:

Traceback (most recent call last):
  File "C:\py\Lib\site-packages\django\core\handlers\exception.py", line 55, in inner
    response = get_response(request)
               ^^^^^^^^^^^^^^^^^^^^^
  File "C:\py\Lib\site-packages\django\core\handlers\base.py", line 197, in _get_response
    response = wrapped_callback(request, *callback_args, **callback_kwargs)
               ^^^^^^^^^^^^^^^^^^^^^^^^^^^^^^^^^^^^^^^^^^^^^^^^^^^^^^^^^^^^
  File "C:\py\Lib\site-packages\django\views\decorators\csrf.py", line 56, in wrapper_view
    return view_func(*args, **kwargs)
           ^^^^^^^^^^^^^^^^^^^^^^^^^^
  File "C:\py\Lib\site-packages\django\views\generic\base.py", line 104, in view
    return self.dispatch(request, *args, **kwargs)
           ^^^^^^^^^^^^^^^^^^^^^^^^^^^^^^^^^^^^^^^
  File "C:\py\Lib\site-packages\rest_framework\views.py", line 509, in dispatch
    response = self.handle_exception(exc)
               ^^^^^^^^^^^^^^^^^^^^^^^^^^
  File "C:\py\Lib\site-packages\rest_framework\views.py", line 469, in handle_exception
    self.raise_uncaught_exception(exc)
  File "C:\py\Lib\site-packages\rest_framework\views.py", line 480, in raise_uncaught_exception
    raise exc
  File "C:\py\Lib\site-packages\rest_framework\views.py", line 506, in dispatch
    response = handler(request, *args, **kwargs)
               ^^^^^^^^^^^^^^^^^^^^^^^^^^^^^^^^^
  File "C:\Users\é\Desktop\Python_django_diploma_dpo\backend\api\views\TagAPIView.py", line 15, in get
    a = super().get(request, *args, **kwargs)
        ^^^^^^^^^^^^^^^^^^^^^^^^^^^^^^^^^^^^^
  File "C:\py\Lib\site-packages\rest_framework\generics.py", line 199, in get
    return self.list(request, *args, **kwargs)
           ^^^^^^^^^^^^^^^^^^^^^^^^^^^^^^^^^^^
  File "C:\py\Lib\site-packages\rest_framework\mixins.py", line 40, in list
    page = self.paginate_queryset(queryset)
           ^^^^^^^^^^^^^^^^^^^^^^^^^^^^^^^^
  File "C:\py\Lib\site-packages\rest_framework\generics.py", line 171, in paginate_queryset
    return self.paginator.paginate_queryset(queryset, self.request, view=self)
           ^^^^^^^^^^^^^^^^^^^^^^^^^^^^^^^^^^^^^^^^^^^^^^^^^^^^^^^^^^^^^^^^^^^
  File "C:\py\Lib\site-packages\rest_framework\pagination.py", line 387, in paginate_queryset
    self.count = self.get_count(queryset)
                 ^^^^^^^^^^^^^^^^^^^^^^^^
  File "C:\py\Lib\site-packages\rest_framework\pagination.py", line 525, in get_count
    return queryset.count()
           ^^^^^^^^^^^^^^^^
  File "C:\py\Lib\site-packages\django\db\models\query.py", line 608, in count
    return self.query.get_count(using=self.db)
           ^^^^^^^^^^^^^^^^^^^^^^^^^^^^^^^^^^^
  File "C:\py\Lib\site-packages\django\db\models\sql\query.py", line 557, in get_count
    return obj.get_aggregation(using, {"__count": Count("*")})["__count"]
           ^^^^^^^^^^^^^^^^^^^^^^^^^^^^^^^^^^^^^^^^^^^^^^^^^^^
  File "C:\py\Lib\site-packages\django\db\models\sql\query.py", line 543, in get_aggregation
    result = compiler.execute_sql(SINGLE)
             ^^^^^^^^^^^^^^^^^^^^^^^^^^^^
  File "C:\py\Lib\site-packages\django\db\models\sql\compiler.py", line 1562, in execute_sql
    cursor.execute(sql, params)
  File "C:\py\Lib\site-packages\django\db\backends\utils.py", line 102, in execute
    return super().execute(sql, params)
           ^^^^^^^^^^^^^^^^^^^^^^^^^^^^
  File "C:\py\Lib\site-packages\django\db\backends\utils.py", line 67, in execute
    return self._execute_with_wrappers(
           ^^^^^^^^^^^^^^^^^^^^^^^^^^^^
  File "C:\py\Lib\site-packages\django\db\backends\utils.py", line 80, in _execute_with_wrappers
    return executor(sql, params, many, context)
           ^^^^^^^^^^^^^^^^^^^^^^^^^^^^^^^^^^^^
  File "C:\py\Lib\site-packages\django\db\backends\utils.py", line 84, in _execute
    with self.db.wrap_database_errors:
  File "C:\py\Lib\site-packages\django\db\utils.py", line 91, in __exit__
    raise dj_exc_value.with_traceback(traceback) from exc_value
  File "C:\py\Lib\site-packages\django\db\backends\utils.py", line 89, in _execute
    return self.cursor.execute(sql, params)
           ^^^^^^^^^^^^^^^^^^^^^^^^^^^^^^^^
  File "C:\py\Lib\site-packages\django\db\backends\sqlite3\base.py", line 328, in execute
    return super().execute(query, params)
           ^^^^^^^^^^^^^^^^^^^^^^^^^^^^^^
django.db.utils.OperationalError: no such table: frontend_tag
[ERROR] - [2023-07-01 18:20:07,540] - [file log.py] - [module log] - [func log_response] - [line_num 241] - Internal Server Error: /api/catalog/
Traceback (most recent call last):
  File "C:\py\Lib\site-packages\django\db\backends\utils.py", line 89, in _execute
    return self.cursor.execute(sql, params)
           ^^^^^^^^^^^^^^^^^^^^^^^^^^^^^^^^
  File "C:\py\Lib\site-packages\django\db\backends\sqlite3\base.py", line 328, in execute
    return super().execute(query, params)
           ^^^^^^^^^^^^^^^^^^^^^^^^^^^^^^
sqlite3.OperationalError: no such table: frontend_product

The above exception was the direct cause of the following exception:

Traceback (most recent call last):
  File "C:\py\Lib\site-packages\django\core\handlers\exception.py", line 55, in inner
    response = get_response(request)
               ^^^^^^^^^^^^^^^^^^^^^
  File "C:\py\Lib\site-packages\django\core\handlers\base.py", line 197, in _get_response
    response = wrapped_callback(request, *callback_args, **callback_kwargs)
               ^^^^^^^^^^^^^^^^^^^^^^^^^^^^^^^^^^^^^^^^^^^^^^^^^^^^^^^^^^^^
  File "C:\py\Lib\site-packages\django\views\decorators\csrf.py", line 56, in wrapper_view
    return view_func(*args, **kwargs)
           ^^^^^^^^^^^^^^^^^^^^^^^^^^
  File "C:\py\Lib\site-packages\django\views\generic\base.py", line 104, in view
    return self.dispatch(request, *args, **kwargs)
           ^^^^^^^^^^^^^^^^^^^^^^^^^^^^^^^^^^^^^^^
  File "C:\py\Lib\site-packages\rest_framework\views.py", line 509, in dispatch
    response = self.handle_exception(exc)
               ^^^^^^^^^^^^^^^^^^^^^^^^^^
  File "C:\py\Lib\site-packages\rest_framework\views.py", line 469, in handle_exception
    self.raise_uncaught_exception(exc)
  File "C:\py\Lib\site-packages\rest_framework\views.py", line 480, in raise_uncaught_exception
    raise exc
  File "C:\py\Lib\site-packages\rest_framework\views.py", line 506, in dispatch
    response = handler(request, *args, **kwargs)
               ^^^^^^^^^^^^^^^^^^^^^^^^^^^^^^^^^
  File "C:\Users\é\Desktop\Python_django_diploma_dpo\backend\api\views\CatalogAPIView.py", line 68, in get
    a = super().get(request, *args, **kwargs)
        ^^^^^^^^^^^^^^^^^^^^^^^^^^^^^^^^^^^^^
  File "C:\py\Lib\site-packages\rest_framework\generics.py", line 199, in get
    return self.list(request, *args, **kwargs)
           ^^^^^^^^^^^^^^^^^^^^^^^^^^^^^^^^^^^
  File "C:\py\Lib\site-packages\rest_framework\mixins.py", line 40, in list
    page = self.paginate_queryset(queryset)
           ^^^^^^^^^^^^^^^^^^^^^^^^^^^^^^^^
  File "C:\py\Lib\site-packages\rest_framework\generics.py", line 171, in paginate_queryset
    return self.paginator.paginate_queryset(queryset, self.request, view=self)
           ^^^^^^^^^^^^^^^^^^^^^^^^^^^^^^^^^^^^^^^^^^^^^^^^^^^^^^^^^^^^^^^^^^^
  File "C:\py\Lib\site-packages\rest_framework\pagination.py", line 204, in paginate_queryset
    self.page = paginator.page(page_number)
                ^^^^^^^^^^^^^^^^^^^^^^^^^^^
  File "C:\py\Lib\site-packages\django\core\paginator.py", line 72, in page
    number = self.validate_number(number)
             ^^^^^^^^^^^^^^^^^^^^^^^^^^^^
  File "C:\py\Lib\site-packages\django\core\paginator.py", line 53, in validate_number
    if number > self.num_pages:
                ^^^^^^^^^^^^^^
  File "C:\py\Lib\site-packages\django\utils\functional.py", line 57, in __get__
    res = instance.__dict__[self.name] = self.func(instance)
                                         ^^^^^^^^^^^^^^^^^^^
  File "C:\py\Lib\site-packages\django\core\paginator.py", line 99, in num_pages
    if self.count == 0 and not self.allow_empty_first_page:
       ^^^^^^^^^^
  File "C:\py\Lib\site-packages\django\utils\functional.py", line 57, in __get__
    res = instance.__dict__[self.name] = self.func(instance)
                                         ^^^^^^^^^^^^^^^^^^^
  File "C:\py\Lib\site-packages\django\core\paginator.py", line 93, in count
    return c()
           ^^^
  File "C:\py\Lib\site-packages\django\db\models\query.py", line 608, in count
    return self.query.get_count(using=self.db)
           ^^^^^^^^^^^^^^^^^^^^^^^^^^^^^^^^^^^
  File "C:\py\Lib\site-packages\django\db\models\sql\query.py", line 557, in get_count
    return obj.get_aggregation(using, {"__count": Count("*")})["__count"]
           ^^^^^^^^^^^^^^^^^^^^^^^^^^^^^^^^^^^^^^^^^^^^^^^^^^^
  File "C:\py\Lib\site-packages\django\db\models\sql\query.py", line 543, in get_aggregation
    result = compiler.execute_sql(SINGLE)
             ^^^^^^^^^^^^^^^^^^^^^^^^^^^^
  File "C:\py\Lib\site-packages\django\db\models\sql\compiler.py", line 1562, in execute_sql
    cursor.execute(sql, params)
  File "C:\py\Lib\site-packages\django\db\backends\utils.py", line 102, in execute
    return super().execute(sql, params)
           ^^^^^^^^^^^^^^^^^^^^^^^^^^^^
  File "C:\py\Lib\site-packages\django\db\backends\utils.py", line 67, in execute
    return self._execute_with_wrappers(
           ^^^^^^^^^^^^^^^^^^^^^^^^^^^^
  File "C:\py\Lib\site-packages\django\db\backends\utils.py", line 80, in _execute_with_wrappers
    return executor(sql, params, many, context)
           ^^^^^^^^^^^^^^^^^^^^^^^^^^^^^^^^^^^^
  File "C:\py\Lib\site-packages\django\db\backends\utils.py", line 84, in _execute
    with self.db.wrap_database_errors:
  File "C:\py\Lib\site-packages\django\db\utils.py", line 91, in __exit__
    raise dj_exc_value.with_traceback(traceback) from exc_value
  File "C:\py\Lib\site-packages\django\db\backends\utils.py", line 89, in _execute
    return self.cursor.execute(sql, params)
           ^^^^^^^^^^^^^^^^^^^^^^^^^^^^^^^^
  File "C:\py\Lib\site-packages\django\db\backends\sqlite3\base.py", line 328, in execute
    return super().execute(query, params)
           ^^^^^^^^^^^^^^^^^^^^^^^^^^^^^^
django.db.utils.OperationalError: no such table: frontend_product
[WARNING] - [2023-07-01 18:20:36,680] - [file log.py] - [module log] - [func log_response] - [line_num 241] - Not Found: /api/sales
[ERROR] - [2023-07-01 18:20:36,747] - [file log.py] - [module log] - [func log_response] - [line_num 241] - Internal Server Error: /api/categories/
Traceback (most recent call last):
  File "C:\py\Lib\site-packages\django\db\backends\utils.py", line 89, in _execute
    return self.cursor.execute(sql, params)
           ^^^^^^^^^^^^^^^^^^^^^^^^^^^^^^^^
  File "C:\py\Lib\site-packages\django\db\backends\sqlite3\base.py", line 328, in execute
    return super().execute(query, params)
           ^^^^^^^^^^^^^^^^^^^^^^^^^^^^^^
sqlite3.OperationalError: no such table: frontend_category

The above exception was the direct cause of the following exception:

Traceback (most recent call last):
  File "C:\py\Lib\site-packages\django\core\handlers\exception.py", line 55, in inner
    response = get_response(request)
               ^^^^^^^^^^^^^^^^^^^^^
  File "C:\py\Lib\site-packages\django\core\handlers\base.py", line 197, in _get_response
    response = wrapped_callback(request, *callback_args, **callback_kwargs)
               ^^^^^^^^^^^^^^^^^^^^^^^^^^^^^^^^^^^^^^^^^^^^^^^^^^^^^^^^^^^^
  File "C:\py\Lib\site-packages\django\views\decorators\csrf.py", line 56, in wrapper_view
    return view_func(*args, **kwargs)
           ^^^^^^^^^^^^^^^^^^^^^^^^^^
  File "C:\py\Lib\site-packages\django\views\generic\base.py", line 104, in view
    return self.dispatch(request, *args, **kwargs)
           ^^^^^^^^^^^^^^^^^^^^^^^^^^^^^^^^^^^^^^^
  File "C:\py\Lib\site-packages\rest_framework\views.py", line 509, in dispatch
    response = self.handle_exception(exc)
               ^^^^^^^^^^^^^^^^^^^^^^^^^^
  File "C:\py\Lib\site-packages\rest_framework\views.py", line 469, in handle_exception
    self.raise_uncaught_exception(exc)
  File "C:\py\Lib\site-packages\rest_framework\views.py", line 480, in raise_uncaught_exception
    raise exc
  File "C:\py\Lib\site-packages\rest_framework\views.py", line 506, in dispatch
    response = handler(request, *args, **kwargs)
               ^^^^^^^^^^^^^^^^^^^^^^^^^^^^^^^^^
  File "C:\Users\é\Desktop\Python_django_diploma_dpo\backend\api\views\CategoriesAPIView.py", line 19, in get
    a = super().get(request, *args, **kwargs)
        ^^^^^^^^^^^^^^^^^^^^^^^^^^^^^^^^^^^^^
  File "C:\py\Lib\site-packages\rest_framework\generics.py", line 199, in get
    return self.list(request, *args, **kwargs)
           ^^^^^^^^^^^^^^^^^^^^^^^^^^^^^^^^^^^
  File "C:\py\Lib\site-packages\rest_framework\mixins.py", line 40, in list
    page = self.paginate_queryset(queryset)
           ^^^^^^^^^^^^^^^^^^^^^^^^^^^^^^^^
  File "C:\py\Lib\site-packages\rest_framework\generics.py", line 171, in paginate_queryset
    return self.paginator.paginate_queryset(queryset, self.request, view=self)
           ^^^^^^^^^^^^^^^^^^^^^^^^^^^^^^^^^^^^^^^^^^^^^^^^^^^^^^^^^^^^^^^^^^^
  File "C:\py\Lib\site-packages\rest_framework\pagination.py", line 387, in paginate_queryset
    self.count = self.get_count(queryset)
                 ^^^^^^^^^^^^^^^^^^^^^^^^
  File "C:\py\Lib\site-packages\rest_framework\pagination.py", line 525, in get_count
    return queryset.count()
           ^^^^^^^^^^^^^^^^
  File "C:\py\Lib\site-packages\django\db\models\query.py", line 608, in count
    return self.query.get_count(using=self.db)
           ^^^^^^^^^^^^^^^^^^^^^^^^^^^^^^^^^^^
  File "C:\py\Lib\site-packages\django\db\models\sql\query.py", line 557, in get_count
    return obj.get_aggregation(using, {"__count": Count("*")})["__count"]
           ^^^^^^^^^^^^^^^^^^^^^^^^^^^^^^^^^^^^^^^^^^^^^^^^^^^
  File "C:\py\Lib\site-packages\django\db\models\sql\query.py", line 543, in get_aggregation
    result = compiler.execute_sql(SINGLE)
             ^^^^^^^^^^^^^^^^^^^^^^^^^^^^
  File "C:\py\Lib\site-packages\django\db\models\sql\compiler.py", line 1562, in execute_sql
    cursor.execute(sql, params)
  File "C:\py\Lib\site-packages\django\db\backends\utils.py", line 102, in execute
    return super().execute(sql, params)
           ^^^^^^^^^^^^^^^^^^^^^^^^^^^^
  File "C:\py\Lib\site-packages\django\db\backends\utils.py", line 67, in execute
    return self._execute_with_wrappers(
           ^^^^^^^^^^^^^^^^^^^^^^^^^^^^
  File "C:\py\Lib\site-packages\django\db\backends\utils.py", line 80, in _execute_with_wrappers
    return executor(sql, params, many, context)
           ^^^^^^^^^^^^^^^^^^^^^^^^^^^^^^^^^^^^
  File "C:\py\Lib\site-packages\django\db\backends\utils.py", line 84, in _execute
    with self.db.wrap_database_errors:
  File "C:\py\Lib\site-packages\django\db\utils.py", line 91, in __exit__
    raise dj_exc_value.with_traceback(traceback) from exc_value
  File "C:\py\Lib\site-packages\django\db\backends\utils.py", line 89, in _execute
    return self.cursor.execute(sql, params)
           ^^^^^^^^^^^^^^^^^^^^^^^^^^^^^^^^
  File "C:\py\Lib\site-packages\django\db\backends\sqlite3\base.py", line 328, in execute
    return super().execute(query, params)
           ^^^^^^^^^^^^^^^^^^^^^^^^^^^^^^
django.db.utils.OperationalError: no such table: frontend_category
[INFO] - [2023-07-01 18:20:46,283] - [file autoreload.py] - [module autoreload] - [func run_with_reloader] - [line_num 668] - Watching for file changes with StatReloader
[ERROR] - [2023-07-01 18:20:51,939] - [file log.py] - [module log] - [func log_response] - [line_num 241] - Internal Server Error: /api/tags/
Traceback (most recent call last):
  File "C:\py\Lib\site-packages\django\db\backends\utils.py", line 89, in _execute
    return self.cursor.execute(sql, params)
           ^^^^^^^^^^^^^^^^^^^^^^^^^^^^^^^^
  File "C:\py\Lib\site-packages\django\db\backends\sqlite3\base.py", line 328, in execute
    return super().execute(query, params)
           ^^^^^^^^^^^^^^^^^^^^^^^^^^^^^^
sqlite3.OperationalError: no such table: frontend_tag

The above exception was the direct cause of the following exception:

Traceback (most recent call last):
  File "C:\py\Lib\site-packages\django\core\handlers\exception.py", line 55, in inner
    response = get_response(request)
               ^^^^^^^^^^^^^^^^^^^^^
  File "C:\py\Lib\site-packages\django\core\handlers\base.py", line 197, in _get_response
    response = wrapped_callback(request, *callback_args, **callback_kwargs)
               ^^^^^^^^^^^^^^^^^^^^^^^^^^^^^^^^^^^^^^^^^^^^^^^^^^^^^^^^^^^^
  File "C:\py\Lib\site-packages\django\views\decorators\csrf.py", line 56, in wrapper_view
    return view_func(*args, **kwargs)
           ^^^^^^^^^^^^^^^^^^^^^^^^^^
  File "C:\py\Lib\site-packages\django\views\generic\base.py", line 104, in view
    return self.dispatch(request, *args, **kwargs)
           ^^^^^^^^^^^^^^^^^^^^^^^^^^^^^^^^^^^^^^^
  File "C:\py\Lib\site-packages\rest_framework\views.py", line 509, in dispatch
    response = self.handle_exception(exc)
               ^^^^^^^^^^^^^^^^^^^^^^^^^^
  File "C:\py\Lib\site-packages\rest_framework\views.py", line 469, in handle_exception
    self.raise_uncaught_exception(exc)
  File "C:\py\Lib\site-packages\rest_framework\views.py", line 480, in raise_uncaught_exception
    raise exc
  File "C:\py\Lib\site-packages\rest_framework\views.py", line 506, in dispatch
    response = handler(request, *args, **kwargs)
               ^^^^^^^^^^^^^^^^^^^^^^^^^^^^^^^^^
  File "C:\Users\é\Desktop\Python_django_diploma_dpo\backend\api\views\TagAPIView.py", line 15, in get
    a = super().get(request, *args, **kwargs)
        ^^^^^^^^^^^^^^^^^^^^^^^^^^^^^^^^^^^^^
  File "C:\py\Lib\site-packages\rest_framework\generics.py", line 199, in get
    return self.list(request, *args, **kwargs)
           ^^^^^^^^^^^^^^^^^^^^^^^^^^^^^^^^^^^
  File "C:\py\Lib\site-packages\rest_framework\mixins.py", line 40, in list
    page = self.paginate_queryset(queryset)
           ^^^^^^^^^^^^^^^^^^^^^^^^^^^^^^^^
  File "C:\py\Lib\site-packages\rest_framework\generics.py", line 171, in paginate_queryset
    return self.paginator.paginate_queryset(queryset, self.request, view=self)
           ^^^^^^^^^^^^^^^^^^^^^^^^^^^^^^^^^^^^^^^^^^^^^^^^^^^^^^^^^^^^^^^^^^^
  File "C:\py\Lib\site-packages\rest_framework\pagination.py", line 387, in paginate_queryset
    self.count = self.get_count(queryset)
                 ^^^^^^^^^^^^^^^^^^^^^^^^
  File "C:\py\Lib\site-packages\rest_framework\pagination.py", line 525, in get_count
    return queryset.count()
           ^^^^^^^^^^^^^^^^
  File "C:\py\Lib\site-packages\django\db\models\query.py", line 608, in count
    return self.query.get_count(using=self.db)
           ^^^^^^^^^^^^^^^^^^^^^^^^^^^^^^^^^^^
  File "C:\py\Lib\site-packages\django\db\models\sql\query.py", line 557, in get_count
    return obj.get_aggregation(using, {"__count": Count("*")})["__count"]
           ^^^^^^^^^^^^^^^^^^^^^^^^^^^^^^^^^^^^^^^^^^^^^^^^^^^
  File "C:\py\Lib\site-packages\django\db\models\sql\query.py", line 543, in get_aggregation
    result = compiler.execute_sql(SINGLE)
             ^^^^^^^^^^^^^^^^^^^^^^^^^^^^
  File "C:\py\Lib\site-packages\django\db\models\sql\compiler.py", line 1562, in execute_sql
    cursor.execute(sql, params)
  File "C:\py\Lib\site-packages\django\db\backends\utils.py", line 102, in execute
    return super().execute(sql, params)
           ^^^^^^^^^^^^^^^^^^^^^^^^^^^^
  File "C:\py\Lib\site-packages\django\db\backends\utils.py", line 67, in execute
    return self._execute_with_wrappers(
           ^^^^^^^^^^^^^^^^^^^^^^^^^^^^
  File "C:\py\Lib\site-packages\django\db\backends\utils.py", line 80, in _execute_with_wrappers
    return executor(sql, params, many, context)
           ^^^^^^^^^^^^^^^^^^^^^^^^^^^^^^^^^^^^
  File "C:\py\Lib\site-packages\django\db\backends\utils.py", line 84, in _execute
    with self.db.wrap_database_errors:
  File "C:\py\Lib\site-packages\django\db\utils.py", line 91, in __exit__
    raise dj_exc_value.with_traceback(traceback) from exc_value
  File "C:\py\Lib\site-packages\django\db\backends\utils.py", line 89, in _execute
    return self.cursor.execute(sql, params)
           ^^^^^^^^^^^^^^^^^^^^^^^^^^^^^^^^
  File "C:\py\Lib\site-packages\django\db\backends\sqlite3\base.py", line 328, in execute
    return super().execute(query, params)
           ^^^^^^^^^^^^^^^^^^^^^^^^^^^^^^
django.db.utils.OperationalError: no such table: frontend_tag
[ERROR] - [2023-07-01 18:20:51,939] - [file log.py] - [module log] - [func log_response] - [line_num 241] - Internal Server Error: /api/catalog/
Traceback (most recent call last):
  File "C:\py\Lib\site-packages\django\db\backends\utils.py", line 89, in _execute
    return self.cursor.execute(sql, params)
           ^^^^^^^^^^^^^^^^^^^^^^^^^^^^^^^^
  File "C:\py\Lib\site-packages\django\db\backends\sqlite3\base.py", line 328, in execute
    return super().execute(query, params)
           ^^^^^^^^^^^^^^^^^^^^^^^^^^^^^^
sqlite3.OperationalError: no such table: frontend_product

The above exception was the direct cause of the following exception:

Traceback (most recent call last):
  File "C:\py\Lib\site-packages\django\core\handlers\exception.py", line 55, in inner
    response = get_response(request)
               ^^^^^^^^^^^^^^^^^^^^^
  File "C:\py\Lib\site-packages\django\core\handlers\base.py", line 197, in _get_response
    response = wrapped_callback(request, *callback_args, **callback_kwargs)
               ^^^^^^^^^^^^^^^^^^^^^^^^^^^^^^^^^^^^^^^^^^^^^^^^^^^^^^^^^^^^
  File "C:\py\Lib\site-packages\django\views\decorators\csrf.py", line 56, in wrapper_view
    return view_func(*args, **kwargs)
           ^^^^^^^^^^^^^^^^^^^^^^^^^^
  File "C:\py\Lib\site-packages\django\views\generic\base.py", line 104, in view
    return self.dispatch(request, *args, **kwargs)
           ^^^^^^^^^^^^^^^^^^^^^^^^^^^^^^^^^^^^^^^
  File "C:\py\Lib\site-packages\rest_framework\views.py", line 509, in dispatch
    response = self.handle_exception(exc)
               ^^^^^^^^^^^^^^^^^^^^^^^^^^
  File "C:\py\Lib\site-packages\rest_framework\views.py", line 469, in handle_exception
    self.raise_uncaught_exception(exc)
  File "C:\py\Lib\site-packages\rest_framework\views.py", line 480, in raise_uncaught_exception
    raise exc
  File "C:\py\Lib\site-packages\rest_framework\views.py", line 506, in dispatch
    response = handler(request, *args, **kwargs)
               ^^^^^^^^^^^^^^^^^^^^^^^^^^^^^^^^^
  File "C:\Users\é\Desktop\Python_django_diploma_dpo\backend\api\views\CatalogAPIView.py", line 68, in get
    a = super().get(request, *args, **kwargs)
        ^^^^^^^^^^^^^^^^^^^^^^^^^^^^^^^^^^^^^
  File "C:\py\Lib\site-packages\rest_framework\generics.py", line 199, in get
    return self.list(request, *args, **kwargs)
           ^^^^^^^^^^^^^^^^^^^^^^^^^^^^^^^^^^^
  File "C:\py\Lib\site-packages\rest_framework\mixins.py", line 40, in list
    page = self.paginate_queryset(queryset)
           ^^^^^^^^^^^^^^^^^^^^^^^^^^^^^^^^
  File "C:\py\Lib\site-packages\rest_framework\generics.py", line 171, in paginate_queryset
    return self.paginator.paginate_queryset(queryset, self.request, view=self)
           ^^^^^^^^^^^^^^^^^^^^^^^^^^^^^^^^^^^^^^^^^^^^^^^^^^^^^^^^^^^^^^^^^^^
  File "C:\py\Lib\site-packages\rest_framework\pagination.py", line 204, in paginate_queryset
    self.page = paginator.page(page_number)
                ^^^^^^^^^^^^^^^^^^^^^^^^^^^
  File "C:\py\Lib\site-packages\django\core\paginator.py", line 72, in page
    number = self.validate_number(number)
             ^^^^^^^^^^^^^^^^^^^^^^^^^^^^
  File "C:\py\Lib\site-packages\django\core\paginator.py", line 53, in validate_number
    if number > self.num_pages:
                ^^^^^^^^^^^^^^
  File "C:\py\Lib\site-packages\django\utils\functional.py", line 57, in __get__
    res = instance.__dict__[self.name] = self.func(instance)
                                         ^^^^^^^^^^^^^^^^^^^
  File "C:\py\Lib\site-packages\django\core\paginator.py", line 99, in num_pages
    if self.count == 0 and not self.allow_empty_first_page:
       ^^^^^^^^^^
  File "C:\py\Lib\site-packages\django\utils\functional.py", line 57, in __get__
    res = instance.__dict__[self.name] = self.func(instance)
                                         ^^^^^^^^^^^^^^^^^^^
  File "C:\py\Lib\site-packages\django\core\paginator.py", line 93, in count
    return c()
           ^^^
  File "C:\py\Lib\site-packages\django\db\models\query.py", line 608, in count
    return self.query.get_count(using=self.db)
           ^^^^^^^^^^^^^^^^^^^^^^^^^^^^^^^^^^^
  File "C:\py\Lib\site-packages\django\db\models\sql\query.py", line 557, in get_count
    return obj.get_aggregation(using, {"__count": Count("*")})["__count"]
           ^^^^^^^^^^^^^^^^^^^^^^^^^^^^^^^^^^^^^^^^^^^^^^^^^^^
  File "C:\py\Lib\site-packages\django\db\models\sql\query.py", line 543, in get_aggregation
    result = compiler.execute_sql(SINGLE)
             ^^^^^^^^^^^^^^^^^^^^^^^^^^^^
  File "C:\py\Lib\site-packages\django\db\models\sql\compiler.py", line 1562, in execute_sql
    cursor.execute(sql, params)
  File "C:\py\Lib\site-packages\django\db\backends\utils.py", line 102, in execute
    return super().execute(sql, params)
           ^^^^^^^^^^^^^^^^^^^^^^^^^^^^
  File "C:\py\Lib\site-packages\django\db\backends\utils.py", line 67, in execute
    return self._execute_with_wrappers(
           ^^^^^^^^^^^^^^^^^^^^^^^^^^^^
  File "C:\py\Lib\site-packages\django\db\backends\utils.py", line 80, in _execute_with_wrappers
    return executor(sql, params, many, context)
           ^^^^^^^^^^^^^^^^^^^^^^^^^^^^^^^^^^^^
  File "C:\py\Lib\site-packages\django\db\backends\utils.py", line 84, in _execute
    with self.db.wrap_database_errors:
  File "C:\py\Lib\site-packages\django\db\utils.py", line 91, in __exit__
    raise dj_exc_value.with_traceback(traceback) from exc_value
  File "C:\py\Lib\site-packages\django\db\backends\utils.py", line 89, in _execute
    return self.cursor.execute(sql, params)
           ^^^^^^^^^^^^^^^^^^^^^^^^^^^^^^^^
  File "C:\py\Lib\site-packages\django\db\backends\sqlite3\base.py", line 328, in execute
    return super().execute(query, params)
           ^^^^^^^^^^^^^^^^^^^^^^^^^^^^^^
django.db.utils.OperationalError: no such table: frontend_product
[ERROR] - [2023-07-01 18:20:52,037] - [file log.py] - [module log] - [func log_response] - [line_num 241] - Internal Server Error: /api/categories/
Traceback (most recent call last):
  File "C:\py\Lib\site-packages\django\db\backends\utils.py", line 89, in _execute
    return self.cursor.execute(sql, params)
           ^^^^^^^^^^^^^^^^^^^^^^^^^^^^^^^^
  File "C:\py\Lib\site-packages\django\db\backends\sqlite3\base.py", line 328, in execute
    return super().execute(query, params)
           ^^^^^^^^^^^^^^^^^^^^^^^^^^^^^^
sqlite3.OperationalError: no such table: frontend_category

The above exception was the direct cause of the following exception:

Traceback (most recent call last):
  File "C:\py\Lib\site-packages\django\core\handlers\exception.py", line 55, in inner
    response = get_response(request)
               ^^^^^^^^^^^^^^^^^^^^^
  File "C:\py\Lib\site-packages\django\core\handlers\base.py", line 197, in _get_response
    response = wrapped_callback(request, *callback_args, **callback_kwargs)
               ^^^^^^^^^^^^^^^^^^^^^^^^^^^^^^^^^^^^^^^^^^^^^^^^^^^^^^^^^^^^
  File "C:\py\Lib\site-packages\django\views\decorators\csrf.py", line 56, in wrapper_view
    return view_func(*args, **kwargs)
           ^^^^^^^^^^^^^^^^^^^^^^^^^^
  File "C:\py\Lib\site-packages\django\views\generic\base.py", line 104, in view
    return self.dispatch(request, *args, **kwargs)
           ^^^^^^^^^^^^^^^^^^^^^^^^^^^^^^^^^^^^^^^
  File "C:\py\Lib\site-packages\rest_framework\views.py", line 509, in dispatch
    response = self.handle_exception(exc)
               ^^^^^^^^^^^^^^^^^^^^^^^^^^
  File "C:\py\Lib\site-packages\rest_framework\views.py", line 469, in handle_exception
    self.raise_uncaught_exception(exc)
  File "C:\py\Lib\site-packages\rest_framework\views.py", line 480, in raise_uncaught_exception
    raise exc
  File "C:\py\Lib\site-packages\rest_framework\views.py", line 506, in dispatch
    response = handler(request, *args, **kwargs)
               ^^^^^^^^^^^^^^^^^^^^^^^^^^^^^^^^^
  File "C:\Users\é\Desktop\Python_django_diploma_dpo\backend\api\views\CategoriesAPIView.py", line 19, in get
    a = super().get(request, *args, **kwargs)
        ^^^^^^^^^^^^^^^^^^^^^^^^^^^^^^^^^^^^^
  File "C:\py\Lib\site-packages\rest_framework\generics.py", line 199, in get
    return self.list(request, *args, **kwargs)
           ^^^^^^^^^^^^^^^^^^^^^^^^^^^^^^^^^^^
  File "C:\py\Lib\site-packages\rest_framework\mixins.py", line 40, in list
    page = self.paginate_queryset(queryset)
           ^^^^^^^^^^^^^^^^^^^^^^^^^^^^^^^^
  File "C:\py\Lib\site-packages\rest_framework\generics.py", line 171, in paginate_queryset
    return self.paginator.paginate_queryset(queryset, self.request, view=self)
           ^^^^^^^^^^^^^^^^^^^^^^^^^^^^^^^^^^^^^^^^^^^^^^^^^^^^^^^^^^^^^^^^^^^
  File "C:\py\Lib\site-packages\rest_framework\pagination.py", line 387, in paginate_queryset
    self.count = self.get_count(queryset)
                 ^^^^^^^^^^^^^^^^^^^^^^^^
  File "C:\py\Lib\site-packages\rest_framework\pagination.py", line 525, in get_count
    return queryset.count()
           ^^^^^^^^^^^^^^^^
  File "C:\py\Lib\site-packages\django\db\models\query.py", line 608, in count
    return self.query.get_count(using=self.db)
           ^^^^^^^^^^^^^^^^^^^^^^^^^^^^^^^^^^^
  File "C:\py\Lib\site-packages\django\db\models\sql\query.py", line 557, in get_count
    return obj.get_aggregation(using, {"__count": Count("*")})["__count"]
           ^^^^^^^^^^^^^^^^^^^^^^^^^^^^^^^^^^^^^^^^^^^^^^^^^^^
  File "C:\py\Lib\site-packages\django\db\models\sql\query.py", line 543, in get_aggregation
    result = compiler.execute_sql(SINGLE)
             ^^^^^^^^^^^^^^^^^^^^^^^^^^^^
  File "C:\py\Lib\site-packages\django\db\models\sql\compiler.py", line 1562, in execute_sql
    cursor.execute(sql, params)
  File "C:\py\Lib\site-packages\django\db\backends\utils.py", line 102, in execute
    return super().execute(sql, params)
           ^^^^^^^^^^^^^^^^^^^^^^^^^^^^
  File "C:\py\Lib\site-packages\django\db\backends\utils.py", line 67, in execute
    return self._execute_with_wrappers(
           ^^^^^^^^^^^^^^^^^^^^^^^^^^^^
  File "C:\py\Lib\site-packages\django\db\backends\utils.py", line 80, in _execute_with_wrappers
    return executor(sql, params, many, context)
           ^^^^^^^^^^^^^^^^^^^^^^^^^^^^^^^^^^^^
  File "C:\py\Lib\site-packages\django\db\backends\utils.py", line 84, in _execute
    with self.db.wrap_database_errors:
  File "C:\py\Lib\site-packages\django\db\utils.py", line 91, in __exit__
    raise dj_exc_value.with_traceback(traceback) from exc_value
  File "C:\py\Lib\site-packages\django\db\backends\utils.py", line 89, in _execute
    return self.cursor.execute(sql, params)
           ^^^^^^^^^^^^^^^^^^^^^^^^^^^^^^^^
  File "C:\py\Lib\site-packages\django\db\backends\sqlite3\base.py", line 328, in execute
    return super().execute(query, params)
           ^^^^^^^^^^^^^^^^^^^^^^^^^^^^^^
django.db.utils.OperationalError: no such table: frontend_category
[INFO] - [2023-07-01 18:22:07,931] - [file autoreload.py] - [module autoreload] - [func run_with_reloader] - [line_num 668] - Watching for file changes with StatReloader
[INFO] - [2023-07-01 18:22:14,360] - [file CatalogAPIView.py] - [module CatalogAPIView] - [func get] - [line_num 70] - [username ] - [Êàòàëîã çàãðóæåí]
[INFO] - [2023-07-01 18:22:14,386] - [file CategoriesAPIView.py] - [module CategoriesAPIView] - [func get] - [line_num 21] - [username ] - [Êàòåãîðèè çàãðóæåíû]
[INFO] - [2023-07-01 18:22:14,388] - [file TagAPIView.py] - [module TagAPIView] - [func get] - [line_num 17] - [username ] - [Òåãè çàãðóæåíû]
[ERROR] - [2023-07-01 18:22:33,922] - [file log.py] - [module log] - [func log_response] - [line_num 241] - Internal Server Error: /admin/login/
Traceback (most recent call last):
  File "C:\py\Lib\site-packages\django\db\backends\utils.py", line 89, in _execute
    return self.cursor.execute(sql, params)
           ^^^^^^^^^^^^^^^^^^^^^^^^^^^^^^^^
  File "C:\py\Lib\site-packages\django\db\backends\sqlite3\base.py", line 328, in execute
    return super().execute(query, params)
           ^^^^^^^^^^^^^^^^^^^^^^^^^^^^^^
sqlite3.OperationalError: no such table: auth_user

The above exception was the direct cause of the following exception:

Traceback (most recent call last):
  File "C:\py\Lib\site-packages\django\core\handlers\exception.py", line 55, in inner
    response = get_response(request)
               ^^^^^^^^^^^^^^^^^^^^^
  File "C:\py\Lib\site-packages\django\core\handlers\base.py", line 197, in _get_response
    response = wrapped_callback(request, *callback_args, **callback_kwargs)
               ^^^^^^^^^^^^^^^^^^^^^^^^^^^^^^^^^^^^^^^^^^^^^^^^^^^^^^^^^^^^
  File "C:\py\Lib\site-packages\django\utils\decorators.py", line 46, in _wrapper
    return bound_method(*args, **kwargs)
           ^^^^^^^^^^^^^^^^^^^^^^^^^^^^^
  File "C:\py\Lib\site-packages\django\views\decorators\cache.py", line 62, in _wrapper_view_func
    response = view_func(request, *args, **kwargs)
               ^^^^^^^^^^^^^^^^^^^^^^^^^^^^^^^^^^^
  File "C:\py\Lib\site-packages\django\contrib\admin\sites.py", line 441, in login
    return LoginView.as_view(**defaults)(request)
           ^^^^^^^^^^^^^^^^^^^^^^^^^^^^^^^^^^^^^^
  File "C:\py\Lib\site-packages\django\views\generic\base.py", line 104, in view
    return self.dispatch(request, *args, **kwargs)
           ^^^^^^^^^^^^^^^^^^^^^^^^^^^^^^^^^^^^^^^
  File "C:\py\Lib\site-packages\django\utils\decorators.py", line 46, in _wrapper
    return bound_method(*args, **kwargs)
           ^^^^^^^^^^^^^^^^^^^^^^^^^^^^^
  File "C:\py\Lib\site-packages\django\views\decorators\debug.py", line 92, in sensitive_post_parameters_wrapper
    return view(request, *args, **kwargs)
           ^^^^^^^^^^^^^^^^^^^^^^^^^^^^^^
  File "C:\py\Lib\site-packages\django\utils\decorators.py", line 46, in _wrapper
    return bound_method(*args, **kwargs)
           ^^^^^^^^^^^^^^^^^^^^^^^^^^^^^
  File "C:\py\Lib\site-packages\django\utils\decorators.py", line 134, in _wrapper_view
    response = view_func(request, *args, **kwargs)
               ^^^^^^^^^^^^^^^^^^^^^^^^^^^^^^^^^^^
  File "C:\py\Lib\site-packages\django\utils\decorators.py", line 46, in _wrapper
    return bound_method(*args, **kwargs)
           ^^^^^^^^^^^^^^^^^^^^^^^^^^^^^
  File "C:\py\Lib\site-packages\django\views\decorators\cache.py", line 62, in _wrapper_view_func
    response = view_func(request, *args, **kwargs)
               ^^^^^^^^^^^^^^^^^^^^^^^^^^^^^^^^^^^
  File "C:\py\Lib\site-packages\django\contrib\auth\views.py", line 90, in dispatch
    return super().dispatch(request, *args, **kwargs)
           ^^^^^^^^^^^^^^^^^^^^^^^^^^^^^^^^^^^^^^^^^^
  File "C:\py\Lib\site-packages\django\views\generic\base.py", line 143, in dispatch
    return handler(request, *args, **kwargs)
           ^^^^^^^^^^^^^^^^^^^^^^^^^^^^^^^^^
  File "C:\py\Lib\site-packages\django\views\generic\edit.py", line 152, in post
    if form.is_valid():
       ^^^^^^^^^^^^^^^
  File "C:\py\Lib\site-packages\django\forms\forms.py", line 201, in is_valid
    return self.is_bound and not self.errors
                                 ^^^^^^^^^^^
  File "C:\py\Lib\site-packages\django\forms\forms.py", line 196, in errors
    self.full_clean()
  File "C:\py\Lib\site-packages\django\forms\forms.py", line 434, in full_clean
    self._clean_form()
  File "C:\py\Lib\site-packages\django\forms\forms.py", line 455, in _clean_form
    cleaned_data = self.clean()
                   ^^^^^^^^^^^^
  File "C:\py\Lib\site-packages\django\contrib\auth\forms.py", line 242, in clean
    self.user_cache = authenticate(
                      ^^^^^^^^^^^^^
  File "C:\py\Lib\site-packages\django\views\decorators\debug.py", line 42, in sensitive_variables_wrapper
    return func(*func_args, **func_kwargs)
           ^^^^^^^^^^^^^^^^^^^^^^^^^^^^^^^
  File "C:\py\Lib\site-packages\django\contrib\auth\__init__.py", line 77, in authenticate
    user = backend.authenticate(request, **credentials)
           ^^^^^^^^^^^^^^^^^^^^^^^^^^^^^^^^^^^^^^^^^^^^
  File "C:\py\Lib\site-packages\django\contrib\auth\backends.py", line 46, in authenticate
    user = UserModel._default_manager.get_by_natural_key(username)
           ^^^^^^^^^^^^^^^^^^^^^^^^^^^^^^^^^^^^^^^^^^^^^^^^^^^^^^^
  File "C:\py\Lib\site-packages\django\contrib\auth\base_user.py", line 54, in get_by_natural_key
    return self.get(**{self.model.USERNAME_FIELD: username})
           ^^^^^^^^^^^^^^^^^^^^^^^^^^^^^^^^^^^^^^^^^^^^^^^^^
  File "C:\py\Lib\site-packages\django\db\models\manager.py", line 87, in manager_method
    return getattr(self.get_queryset(), name)(*args, **kwargs)
           ^^^^^^^^^^^^^^^^^^^^^^^^^^^^^^^^^^^^^^^^^^^^^^^^^^^
  File "C:\py\Lib\site-packages\django\db\models\query.py", line 633, in get
    num = len(clone)
          ^^^^^^^^^^
  File "C:\py\Lib\site-packages\django\db\models\query.py", line 380, in __len__
    self._fetch_all()
  File "C:\py\Lib\site-packages\django\db\models\query.py", line 1881, in _fetch_all
    self._result_cache = list(self._iterable_class(self))
                         ^^^^^^^^^^^^^^^^^^^^^^^^^^^^^^^^
  File "C:\py\Lib\site-packages\django\db\models\query.py", line 91, in __iter__
    results = compiler.execute_sql(
              ^^^^^^^^^^^^^^^^^^^^^
  File "C:\py\Lib\site-packages\django\db\models\sql\compiler.py", line 1562, in execute_sql
    cursor.execute(sql, params)
  File "C:\py\Lib\site-packages\django\db\backends\utils.py", line 102, in execute
    return super().execute(sql, params)
           ^^^^^^^^^^^^^^^^^^^^^^^^^^^^
  File "C:\py\Lib\site-packages\django\db\backends\utils.py", line 67, in execute
    return self._execute_with_wrappers(
           ^^^^^^^^^^^^^^^^^^^^^^^^^^^^
  File "C:\py\Lib\site-packages\django\db\backends\utils.py", line 80, in _execute_with_wrappers
    return executor(sql, params, many, context)
           ^^^^^^^^^^^^^^^^^^^^^^^^^^^^^^^^^^^^
  File "C:\py\Lib\site-packages\django\db\backends\utils.py", line 84, in _execute
    with self.db.wrap_database_errors:
  File "C:\py\Lib\site-packages\django\db\utils.py", line 91, in __exit__
    raise dj_exc_value.with_traceback(traceback) from exc_value
  File "C:\py\Lib\site-packages\django\db\backends\utils.py", line 89, in _execute
    return self.cursor.execute(sql, params)
           ^^^^^^^^^^^^^^^^^^^^^^^^^^^^^^^^
  File "C:\py\Lib\site-packages\django\db\backends\sqlite3\base.py", line 328, in execute
    return super().execute(query, params)
           ^^^^^^^^^^^^^^^^^^^^^^^^^^^^^^
django.db.utils.OperationalError: no such table: auth_user
[INFO] - [2023-07-01 16:38:48,126] - [file autoreload.py] - [module autoreload] - [func trigger_reload] - [line_num 266] - /mnt/c/Users/borod/PycharmProjects/Python_django_diploma_dpo/backend/frontend/__init__.py changed, reloading.
[INFO] - [2023-07-01 16:38:49,641] - [file autoreload.py] - [module autoreload] - [func run_with_reloader] - [line_num 677] - Watching for file changes with StatReloader
[INFO] - [2023-07-01 16:39:19,551] - [file BannersAPIView.py] - [module BannersAPIView] - [func get] - [line_num 21] - [username ] - [ÐÐ°Ð½ÐµÑÑ Ð·Ð°Ð³ÑÑÐ¶ÐµÐ½Ñ]
[INFO] - [2023-07-01 16:39:33,100] - [file BannersAPIView.py] - [module BannersAPIView] - [func get] - [line_num 21] - [username ] - [ÐÐ°Ð½ÐµÑÑ Ð·Ð°Ð³ÑÑÐ¶ÐµÐ½Ñ]
[INFO] - [2023-07-01 16:39:33,127] - [file LimitedProductAPIView.py] - [module LimitedProductAPIView] - [func get] - [line_num 23] - [username ] - [ÐÑÐ¾Ð´ÑÐºÑÑ Ñ Ð¾Ð³ÑÐ°Ð½Ð¸ÑÐµÐ½Ð½ÑÐ¼ ÑÐ¸ÑÐ°Ð¶Ð¾Ð¼ Ð·Ð°Ð³ÑÑÐ¶ÐµÐ½Ñ]
[INFO] - [2023-07-01 16:39:33,133] - [file PopularProductAPIView.py] - [module PopularProductAPIView] - [func get] - [line_num 25] - [username ] - [ÐÐ¾Ð¿ÑÐ»ÑÑÐ½ÑÐµ Ð¿ÑÐ¾Ð´ÑÐºÑÑ Ð·Ð°Ð³ÑÑÐ¶ÐµÐ½Ñ]
[INFO] - [2023-07-01 16:39:33,139] - [file CategoriesAPIView.py] - [module CategoriesAPIView] - [func get] - [line_num 21] - [username ] - [ÐÐ°ÑÐµÐ³Ð¾ÑÐ¸Ð¸ Ð·Ð°Ð³ÑÑÐ¶ÐµÐ½Ñ]
[INFO] - [2023-07-01 16:39:33,233] - [file LimitedProductAPIView.py] - [module LimitedProductAPIView] - [func get] - [line_num 23] - [username ] - [ÐÑÐ¾Ð´ÑÐºÑÑ Ñ Ð¾Ð³ÑÐ°Ð½Ð¸ÑÐµÐ½Ð½ÑÐ¼ ÑÐ¸ÑÐ°Ð¶Ð¾Ð¼ Ð·Ð°Ð³ÑÑÐ¶ÐµÐ½Ñ]
[INFO] - [2023-07-01 16:39:48,824] - [file CatalogAPIView.py] - [module CatalogAPIView] - [func get] - [line_num 70] - [username ] - [ÐÐ°ÑÐ°Ð»Ð¾Ð³ Ð·Ð°Ð³ÑÑÐ¶ÐµÐ½]
[INFO] - [2023-07-01 16:39:48,887] - [file TagAPIView.py] - [module TagAPIView] - [func get] - [line_num 17] - [username ] - [Ð¢ÐµÐ³Ð¸ Ð·Ð°Ð³ÑÑÐ¶ÐµÐ½Ñ]
[INFO] - [2023-07-01 16:39:48,891] - [file CategoriesAPIView.py] - [module CategoriesAPIView] - [func get] - [line_num 21] - [username ] - [ÐÐ°ÑÐµÐ³Ð¾ÑÐ¸Ð¸ Ð·Ð°Ð³ÑÑÐ¶ÐµÐ½Ñ]
[WARNING] - [2023-07-01 16:42:09,854] - [file log.py] - [module log] - [func log_response] - [line_num 241] - Not Found: /catalog/rus
[WARNING] - [2023-07-01 16:42:15,350] - [file log.py] - [module log] - [func log_response] - [line_num 241] - Not Found: /catalog/ru
[INFO] - [2023-07-01 16:42:21,656] - [file CatalogAPIView.py] - [module CatalogAPIView] - [func get] - [line_num 70] - [username ] - [ÐÐ°ÑÐ°Ð»Ð¾Ð³ Ð·Ð°Ð³ÑÑÐ¶ÐµÐ½]
[INFO] - [2023-07-01 16:42:21,679] - [file TagAPIView.py] - [module TagAPIView] - [func get] - [line_num 17] - [username ] - [Ð¢ÐµÐ³Ð¸ Ð·Ð°Ð³ÑÑÐ¶ÐµÐ½Ñ]
[INFO] - [2023-07-01 16:42:21,688] - [file CategoriesAPIView.py] - [module CategoriesAPIView] - [func get] - [line_num 21] - [username ] - [ÐÐ°ÑÐµÐ³Ð¾ÑÐ¸Ð¸ Ð·Ð°Ð³ÑÑÐ¶ÐµÐ½Ñ]
[INFO] - [2023-07-01 16:42:25,546] - [file LimitedProductAPIView.py] - [module LimitedProductAPIView] - [func get] - [line_num 23] - [username ] - [ÐÑÐ¾Ð´ÑÐºÑÑ Ñ Ð¾Ð³ÑÐ°Ð½Ð¸ÑÐµÐ½Ð½ÑÐ¼ ÑÐ¸ÑÐ°Ð¶Ð¾Ð¼ Ð·Ð°Ð³ÑÑÐ¶ÐµÐ½Ñ]
[INFO] - [2023-07-01 16:42:25,557] - [file BannersAPIView.py] - [module BannersAPIView] - [func get] - [line_num 21] - [username ] - [ÐÐ°Ð½ÐµÑÑ Ð·Ð°Ð³ÑÑÐ¶ÐµÐ½Ñ]
[INFO] - [2023-07-01 16:42:25,559] - [file CategoriesAPIView.py] - [module CategoriesAPIView] - [func get] - [line_num 21] - [username ] - [ÐÐ°ÑÐµÐ³Ð¾ÑÐ¸Ð¸ Ð·Ð°Ð³ÑÑÐ¶ÐµÐ½Ñ]
[INFO] - [2023-07-01 16:42:25,566] - [file PopularProductAPIView.py] - [module PopularProductAPIView] - [func get] - [line_num 25] - [username ] - [ÐÐ¾Ð¿ÑÐ»ÑÑÐ½ÑÐµ Ð¿ÑÐ¾Ð´ÑÐºÑÑ Ð·Ð°Ð³ÑÑÐ¶ÐµÐ½Ñ]
[INFO] - [2023-07-01 16:42:25,599] - [file LimitedProductAPIView.py] - [module LimitedProductAPIView] - [func get] - [line_num 23] - [username ] - [ÐÑÐ¾Ð´ÑÐºÑÑ Ñ Ð¾Ð³ÑÐ°Ð½Ð¸ÑÐµÐ½Ð½ÑÐ¼ ÑÐ¸ÑÐ°Ð¶Ð¾Ð¼ Ð·Ð°Ð³ÑÑÐ¶ÐµÐ½Ñ]
[WARNING] - [2023-07-01 16:42:28,150] - [file log.py] - [module log] - [func log_response] - [line_num 241] - Not Found: /api/sales
[INFO] - [2023-07-01 16:42:28,228] - [file CategoriesAPIView.py] - [module CategoriesAPIView] - [func get] - [line_num 21] - [username ] - [ÐÐ°ÑÐµÐ³Ð¾ÑÐ¸Ð¸ Ð·Ð°Ð³ÑÑÐ¶ÐµÐ½Ñ]
[INFO] - [2023-07-01 16:42:31,496] - [file CatalogAPIView.py] - [module CatalogAPIView] - [func get] - [line_num 70] - [username ] - [ÐÐ°ÑÐ°Ð»Ð¾Ð³ Ð·Ð°Ð³ÑÑÐ¶ÐµÐ½]
[INFO] - [2023-07-01 16:42:31,557] - [file TagAPIView.py] - [module TagAPIView] - [func get] - [line_num 17] - [username ] - [Ð¢ÐµÐ³Ð¸ Ð·Ð°Ð³ÑÑÐ¶ÐµÐ½Ñ]
[INFO] - [2023-07-01 16:42:31,560] - [file CategoriesAPIView.py] - [module CategoriesAPIView] - [func get] - [line_num 21] - [username ] - [ÐÐ°ÑÐµÐ³Ð¾ÑÐ¸Ð¸ Ð·Ð°Ð³ÑÑÐ¶ÐµÐ½Ñ]
[INFO] - [2023-07-01 16:42:32,704] - [file CategoriesAPIView.py] - [module CategoriesAPIView] - [func get] - [line_num 21] - [username ] - [ÐÐ°ÑÐµÐ³Ð¾ÑÐ¸Ð¸ Ð·Ð°Ð³ÑÑÐ¶ÐµÐ½Ñ]
[INFO] - [2023-07-03 09:20:47,642] - [file autoreload.py] - [module autoreload] - [func trigger_reload] - [line_num 266] - /mnt/c/Users/borod/PycharmProjects/Python_django_diploma_dpo/backend/backend/urls.py changed, reloading.
[INFO] - [2023-07-03 09:20:48,701] - [file autoreload.py] - [module autoreload] - [func run_with_reloader] - [line_num 677] - Watching for file changes with StatReloader
